Workbook

Sheet Informe cualitativo
A1: Nº | B1: APELLIDOS | C1: NOMBRE | D1: RENDIMIENTO EN CLASE | E1: INTERÉS Y ESFUERZO | F1: PARTICIPACIÓN EN CLASE | G1: COLABORA CON LOS COMPAÑEROS | H1: CALIDAD TÉCNICA | I1: VALORACIÓN GLOBAL (trayectoria: Actitud y aptitud) | J1: RECOMENDARÍAS A ESTE ALUMNO PARA TRABAJAR EN UNA EMPRESA | K1: OBSERVACIONES-COMENTARIOS
A2: 1 | B2: Álvarez García | C2: Diego | D2: 8 | E2: 7 | F2: 8 | G2: 4 | H2: 7 | I2: 7 | J2: Si | K2: Tiene buen nivel, muy lider
A3: 2 | B3: Amaya Cardona | C3: Steven | D3: 8 | E3: 7 | F3: 8 | G3: 5 | H3: 7 | I3: 7 | J3: Si | K3: Va haciendo los trabajos, es puntual.
A4: 3 | B4: Arequipa Cueva | C4: Luis Leonardo | D4: 8 | E4: 7 | F4: 8 | G4: 5 | H4: 6 | I4: 7 | J4: Si | K4: Está un poco despistado. hay que marcarlo un poco.
A5: 4 | B5: Carreras Delgado | C5: Enrique | D5: 8 | E5: 7 | F5: 8 | G5: 5 | H5: 8 | I5: 7 | J5: Si | K5: Buen alumno, trabajador, entrega los trabajos.
A6: 5 | B6: Danci Koblicska | C6: Catalin Grigore | D6: 9 | E6: 8 | F6: 9 | G6: 9 | H6: 8 | I6: 9 | J6: Si | K6: Responsable, es muchas veces el representante de los alumnos
A7: 6 | B7: Diz Gago | C7: Daniel | D7: 9 | E7: 8 | F7: 9 | G7: 9 | H7: 9 | I7: 8 | J7: Si | K7: Bien, colabora y ayuda, tiene buen nivel y quiere aprender.
A8: 7 | B8: García Bedoya | C8: Bryan Steven | D8: 8 | E8: 7 | F8: 8 | G8: 6 | H8: 6 | I8: 8 | J8: Si | K8: Un poco lento, pero va realizando las cosas
A9: 8 | B9: González Carreras | C9: Daniel | D9: 8 | E9: 7 | F9: 8 | G9: 7 | H9: 9 | I9: 8 | J9: Si | K9: Despistado, serio y aplicado
A10: 9 | B10: Hebrero Requena | C10: Ismael | D10: 8 | E10: 7 | F10: 8 | G10: 7 | H10: 8 | I10: 7 | J10: Si | K10: Colabora, tiene buen nivel.
A11: 10 | B11: Lamata Ramos | C11: Gonzalo | D11: 7 | E11: 6 | F11: 7 | G11: 4 | H11: 6 | I11: 6 | J11: Si | K11: Problemas para trabajar en equipo.
A12: 11 | B12: López León | C12: José Alejandro | D12: 7 | E12: 6 | F12: 7 | G12: 5 | H12: 7 | I12: 6 | J12: Si | K12: Realiza los ejercicios y atiende en clase
A13: 12 | B13: Luengo Prados | C13: Iván | D13: 7 | E13: 6 | F13: 7 | G13: 4 | H13: 7 | I13: 6 | J13: Si | K13: Colaborativo, le faltaría trabajar un poco más.
... A28: 27 | B28: Villar Fernandes | C28: Jaime | D28: 7 | E28: 6 | F28: 7 | G28: 5 | H28: 6 | I28: 5 | J28: Si | K28: Se aplica y hace los ejercicios de una forma muy correcta.
B32: PUNTUAR TODOS LOS APARTADOS DEL 1 AL 10. El 1 es la peor nota y 10 la mejor

Sheet Total asistencia bueno
A1: Nº | B1: APELLIDOS | C1: NOMBRE | D1: EMAIL | E1: TOTAL FALTAS Y RETRASOS SIN JUSTIFICAR | F1: PORCENTAJE ASISTENCIA (O FALTAS JUSTIFICADAS) | G1: Nº de Faltas Total F y R Totales | H1: Porcentaje de Asistencia F (si contamos los días completos de asistencia y no contamos los R y/o SAF) | I1: Nº de Faltas Total F Totales | J1: R+RJ+SAF+SAFJ | K1: Nº total de R y SAF, dividido entre 2, más las F (justificadas o no) | L1: Porcentaje de asistencia real. Para calcular diploma (80%) o para dejar el curso (-75%) | M1: Porcentaje de Asistencia F y R. PARA CALCULAR PRÁCTICAS EN EMPRESA
A2: =Listado!A4 -> 1 | B2: =Listado!B4 -> Alonso Mansilla | C2: =Listado!C4 -> Javier | D2: =Listado!E4 -> javier.alonsomansilla@tajamar365.com | E2: =SUM(Octubre!O4,Noviembre!O4,Diciembre!O4,Enero!O5,Febrero!O4,Marzo!O4,Abril!O4,Mayo!O4,Junio!O4) -> 0 | F2: =IF($D$31=0,"",100-((E2*100)/$D$31)) -> 100 | G2: =SUM(Octubre!Q4,Noviembre!Q4,Diciembre!Q4,Enero!Q5,Febrero!Q4,Marzo!Q4,Abril!Q4,Mayo!Q4,Junio!Q4) -> 0 | H2: =IF($D$31=0,"",100-((I2*100)/$D$31)) -> 100 | I2: =SUM(Octubre!P4,Noviembre!P4,Diciembre!P4,Enero!P5,Febrero!P4,Marzo!P4,Abril!P4,Mayo!P4,Junio!P4) -> 0 | J2: =SUM(Octubre!J4,Octubre!K4,Octubre!M4,Octubre!N4,Noviembre!J4,Noviembre!K4,Noviembre!M4,Noviembre!N4,Diciembre!J4,Diciembre!K4,Diciembre!M4,Diciembre!N4,Enero!J5,Enero!K5,Enero!M5,Enero!N5,Febrero!J4,Febrero!K4,Febrero!M4,Febrero!N4,Marzo!J4,Marzo!K4,Marzo!M4,Marzo!N4,Abril!J4,Abril!K4,Abril!M4,Abril!N4,Mayo!J4,Mayo!K4,Mayo!M4,Mayo!N4,Junio!J4,Junio!K4,Junio!M4,Junio!N4) -> 0 | K2: =(J2/2)+I2 -> 0 | L2: =IF($D$31=0,"",100-((K2*100)/$D$31)) -> 100 | M2: =IF($D$31=0,"",100-((G2*100)/$D$31)) -> 100
A3: =Listado!A5 -> 2 | B3: =Listado!B5 -> Barbacid Fernández | C3: =Listado!C5 -> Alberto | D3: =Listado!E5 -> alberto.barbacid@tajamar365.com | E3: =SUM(Octubre!O5,Noviembre!O5,Diciembre!O5,Enero!O6,Febrero!O5,Marzo!O5,Abril!O5,Mayo!O5,Junio!O5) -> 0 | F3: =IF($D$31=0,"",100-((E3*100)/$D$31)) -> 100 | G3: =SUM(Octubre!Q5,Noviembre!Q5,Diciembre!Q5,Enero!Q6,Febrero!Q5,Marzo!Q5,Abril!Q5,Mayo!Q5,Junio!Q5) -> 0 | H3: =IF($D$31=0,"",100-((I3*100)/$D$31)) -> 100 | I3: =SUM(Octubre!P5,Noviembre!P5,Diciembre!P5,Enero!P6,Febrero!P5,Marzo!P5,Abril!P5,Mayo!P5,Junio!P5) -> 0 | J3: =SUM(Octubre!J5,Octubre!K5,Octubre!M5,Octubre!N5,Noviembre!J5,Noviembre!K5,Noviembre!M5,Noviembre!N5,Diciembre!J5,Diciembre!K5,Diciembre!M5,Diciembre!N5,Enero!J6,Enero!K6,Enero!M6,Enero!N6,Febrero!J5,Febrero!K5,Febrero!M5,Febrero!N5,Marzo!J5,Marzo!K5,Marzo!M5,Marzo!N5,Abril!J5,Abril!K5,Abril!M5,Abril!N5,Mayo!J5,Mayo!K5,Mayo!M5,Mayo!N5,Junio!J5,Junio!K5,Junio!M5,Junio!N5) -> 0 | K3: =(J3/2)+I3 -> 0 | L3: =IF($D$31=0,"",100-((K3*100)/$D$31)) -> 100 | M3: =IF($D$31=0,"",100-((G3*100)/$D$31)) -> 100
A4: =Listado!A6 -> 3 | B4: =Listado!B6 -> Bayas Sarzosa | C4: =Listado!C6 -> Kevin | D4: =Listado!E6 -> kevin.bayas@tajamar365.com | E4: =SUM(Octubre!O6,Noviembre!O6,Diciembre!O6,Enero!O7,Febrero!O6,Marzo!O6,Abril!O6,Mayo!O6,Junio!O6) -> 0 | F4: =IF($D$31=0,"",100-((E4*100)/$D$31)) -> 100 | G4: =SUM(Octubre!Q6,Noviembre!Q6,Diciembre!Q6,Enero!Q7,Febrero!Q6,Marzo!Q6,Abril!Q6,Mayo!Q6,Junio!Q6) -> 0 | H4: =IF($D$31=0,"",100-((I4*100)/$D$31)) -> 100 | I4: =SUM(Octubre!P6,Noviembre!P6,Diciembre!P6,Enero!P7,Febrero!P6,Marzo!P6,Abril!P6,Mayo!P6,Junio!P6) -> 0 | J4: =SUM(Octubre!J6,Octubre!K6,Octubre!M6,Octubre!N6,Noviembre!J6,Noviembre!K6,Noviembre!M6,Noviembre!N6,Diciembre!J6,Diciembre!K6,Diciembre!M6,Diciembre!N6,Enero!J7,Enero!K7,Enero!M7,Enero!N7,Febrero!J6,Febrero!K6,Febrero!M6,Febrero!N6,Marzo!J6,Marzo!K6,Marzo!M6,Marzo!N6,Abril!J6,Abril!K6,Abril!M6,Abril!N6,Mayo!J6,Mayo!K6,Mayo!M6,Mayo!N6,Junio!J6,Junio!K6,Junio!M6,Junio!N6) -> 0 | K4: =(J4/2)+I4 -> 0 | L4: =IF($D$31=0,"",100-((K4*100)/$D$31)) -> 100 | M4: =IF($D$31=0,"",100-((G4*100)/$D$31)) -> 100
A5: =Listado!A7 -> 4 | B5: =Listado!B7 -> Cánovas López | C5: =Listado!C7 -> Alejandro | D5: =Listado!E7 -> alejandro.canovas@tajamar365.com | E5: =SUM(Octubre!O7,Noviembre!O7,Diciembre!O7,Enero!O8,Febrero!O7,Marzo!O7,Abril!O7,Mayo!O7,Junio!O7) -> 0 | F5: =IF($D$31=0,"",100-((E5*100)/$D$31)) -> 100 | G5: =SUM(Octubre!Q7,Noviembre!Q7,Diciembre!Q7,Enero!Q8,Febrero!Q7,Marzo!Q7,Abril!Q7,Mayo!Q7,Junio!Q7) -> 0 | H5: =IF($D$31=0,"",100-((I5*100)/$D$31)) -> 100 | I5: =SUM(Octubre!P7,Noviembre!P7,Diciembre!P7,Enero!P8,Febrero!P7,Marzo!P7,Abril!P7,Mayo!P7,Junio!P7) -> 0 | J5: =SUM(Octubre!J7,Octubre!K7,Octubre!M7,Octubre!N7,Noviembre!J7,Noviembre!K7,Noviembre!M7,Noviembre!N7,Diciembre!J7,Diciembre!K7,Diciembre!M7,Diciembre!N7,Enero!J8,Enero!K8,Enero!M8,Enero!N8,Febrero!J7,Febrero!K7,Febrero!M7,Febrero!N7,Marzo!J7,Marzo!K7,Marzo!M7,Marzo!N7,Abril!J7,Abril!K7,Abril!M7,Abril!N7,Mayo!J7,Mayo!K7,Mayo!M7,Mayo!N7,Junio!J7,Junio!K7,Junio!M7,Junio!N7) -> 0 | K5: =(J5/2)+I5 -> 0 | L5: =IF($D$31=0,"",100-((K5*100)/$D$31)) -> 100 | M5: =IF($D$31=0,"",100-((G5*100)/$D$31)) -> 100
A6: =Listado!#REF! -> #REF! | B6: =Listado!#REF! -> #REF! | C6: =Listado!#REF! -> #REF! | D6: =Listado!#REF! -> #REF! | E6: =SUM(Octubre!#REF!,Noviembre!#REF!,Diciembre!#REF!,Enero!#REF!,Febrero!#REF!,Marzo!#REF!,Abril!#REF!,Mayo!#REF!,Junio!#REF!) -> #REF! | F6: =IF($D$31=0,"",100-((E6*100)/$D$31)) -> #REF! | G6: =SUM(Octubre!#REF!,Noviembre!#REF!,Diciembre!#REF!,Enero!#REF!,Febrero!#REF!,Marzo!#REF!,Abril!#REF!,Mayo!#REF!,Junio!#REF!) -> #REF! | H6: =IF($D$31=0,"",100-((I6*100)/$D$31)) -> #REF! | I6: =SUM(Octubre!#REF!,Noviembre!#REF!,Diciembre!#REF!,Enero!#REF!,Febrero!#REF!,Marzo!#REF!,Abril!#REF!,Mayo!#REF!,Junio!#REF!) -> #REF! | J6: =SUM(Octubre!#REF!,Octubre!#REF!,Octubre!#REF!,Octubre!#REF!,Noviembre!#REF!,Noviembre!#REF!,Noviembre!#REF!,Noviembre!#REF!,Diciembre!#REF!,Diciembre!#REF!,Diciembre!#REF!,Diciembre!#REF!,Enero!#REF!,Enero!#REF!,Enero!#REF!,Enero!#REF!,Febrero!#REF!,Febrero!#REF!,Febrero!#REF!,Febrero!#REF!,Marzo!#REF!,Marzo!#REF!,Marzo!#REF!,Marzo!#REF!,Abril!#REF!,Abril!#REF!,Abril!#REF!,Abril!#REF!,Mayo!#REF!,Mayo!#REF!,Mayo!#REF!,Mayo!#REF!,Junio!#REF!,Junio!#REF!,Junio!#REF!,Junio!#REF!) -> #REF! | K6: =(J6/2)+I6 -> #REF! | L6: =IF($D$31=0,"",100-((K6*100)/$D$31)) -> #REF! | M6: =IF($D$31=0,"",100-((G6*100)/$D$31)) -> #REF!
A7: =Listado!A8 -> 5 | B7: =Listado!B8 -> Cardona Hernández | C7: =Listado!C8 -> Diego | D7: =Listado!E8 -> diego.cardona@tajamar365.com | E7: =SUM(Octubre!O8,Noviembre!O8,Diciembre!O8,Enero!O9,Febrero!O8,Marzo!O8,Abril!O8,Mayo!O8,Junio!O8) -> 0 | F7: =IF($D$31=0,"",100-((E7*100)/$D$31)) -> 100 | G7: =SUM(Octubre!Q8,Noviembre!Q8,Diciembre!Q8,Enero!Q9,Febrero!Q8,Marzo!Q8,Abril!Q8,Mayo!Q8,Junio!Q8) -> 0 | H7: =IF($D$31=0,"",100-((I7*100)/$D$31)) -> 100 | I7: =SUM(Octubre!P8,Noviembre!P8,Diciembre!P8,Enero!P9,Febrero!P8,Marzo!P8,Abril!P8,Mayo!P8,Junio!P8) -> 0 | J7: =SUM(Octubre!J8,Octubre!K8,Octubre!M8,Octubre!N8,Noviembre!J8,Noviembre!K8,Noviembre!M8,Noviembre!N8,Diciembre!J8,Diciembre!K8,Diciembre!M8,Diciembre!N8,Enero!J9,Enero!K9,Enero!M9,Enero!N9,Febrero!J8,Febrero!K8,Febrero!M8,Febrero!N8,Marzo!J8,Marzo!K8,Marzo!M8,Marzo!N8,Abril!J8,Abril!K8,Abril!M8,Abril!N8,Mayo!J8,Mayo!K8,Mayo!M8,Mayo!N8,Junio!J8,Junio!K8,Junio!M8,Junio!N8) -> 0 | K7: =(J7/2)+I7 -> 0 | L7: =IF($D$31=0,"",100-((K7*100)/$D$31)) -> 100 | M7: =IF($D$31=0,"",100-((G7*100)/$D$31)) -> 100
A8: =Listado!A9 -> 6 | B8: =Listado!B9 -> Casco Valero | C8: =Listado!C9 -> Álvaro | D8: =Listado!E9 -> alvaro.casco@tajamar365.com | E8: =SUM(Octubre!O9,Noviembre!O9,Diciembre!O9,Enero!O10,Febrero!O9,Marzo!O9,Abril!O9,Mayo!O9,Junio!O9) -> 0 | F8: =IF($D$31=0,"",100-((E8*100)/$D$31)) -> 100 | G8: =SUM(Octubre!Q9,Noviembre!Q9,Diciembre!Q9,Enero!Q10,Febrero!Q9,Marzo!Q9,Abril!Q9,Mayo!Q9,Junio!Q9) -> 0 | H8: =IF($D$31=0,"",100-((I8*100)/$D$31)) -> 100 | I8: =SUM(Octubre!P9,Noviembre!P9,Diciembre!P9,Enero!P10,Febrero!P9,Marzo!P9,Abril!P9,Mayo!P9,Junio!P9) -> 0 | J8: =SUM(Octubre!J9,Octubre!K9,Octubre!M9,Octubre!N9,Noviembre!J9,Noviembre!K9,Noviembre!M9,Noviembre!N9,Diciembre!J9,Diciembre!K9,Diciembre!M9,Diciembre!N9,Enero!J10,Enero!K10,Enero!M10,Enero!N10,Febrero!J9,Febrero!K9,Febrero!M9,Febrero!N9,Marzo!J9,Marzo!K9,Marzo!M9,Marzo!N9,Abril!J9,Abril!K9,Abril!M9,Abril!N9,Mayo!J9,Mayo!K9,Mayo!M9,Mayo!N9,Junio!J9,Junio!K9,Junio!M9,Junio!N9) -> 0 | K8: =(J8/2)+I8 -> 0 | L8: =IF($D$31=0,"",100-((K8*100)/$D$31)) -> 100 | M8: =IF($D$31=0,"",100-((G8*100)/$D$31)) -> 100
A9: =Listado!A10 -> 7 | B9: =Listado!B10 -> Cobo Marcos | C9: =Listado!C10 -> Alejandro | D9: =Listado!E10 -> alejandro.cobo@tajamar365.com | E9: =SUM(Octubre!O10,Noviembre!O10,Diciembre!O10,Enero!O11,Febrero!O10,Marzo!O10,Abril!O10,Mayo!O10,Junio!O10) -> 0 | F9: =IF($D$31=0,"",100-((E9*100)/$D$31)) -> 100 | G9: =SUM(Octubre!Q10,Noviembre!Q10,Diciembre!Q10,Enero!Q11,Febrero!Q10,Marzo!Q10,Abril!Q10,Mayo!Q10,Junio!Q10) -> 0 | H9: =IF($D$31=0,"",100-((I9*100)/$D$31)) -> 100 | I9: =SUM(Octubre!P10,Noviembre!P10,Diciembre!P10,Enero!P11,Febrero!P10,Marzo!P10,Abril!P10,Mayo!P10,Junio!P10) -> 0 | J9: =SUM(Octubre!J10,Octubre!K10,Octubre!M10,Octubre!N10,Noviembre!J10,Noviembre!K10,Noviembre!M10,Noviembre!N10,Diciembre!J10,Diciembre!K10,Diciembre!M10,Diciembre!N10,Enero!J11,Enero!K11,Enero!M11,Enero!N11,Febrero!J10,Febrero!K10,Febrero!M10,Febrero!N10,Marzo!J10,Marzo!K10,Marzo!M10,Marzo!N10,Abril!J10,Abril!K10,Abril!M10,Abril!N10,Mayo!J10,Mayo!K10,Mayo!M10,Mayo!N10,Junio!J10,Junio!K10,Junio!M10,Junio!N10) -> 0 | K9: =(J9/2)+I9 -> 0 | L9: =IF($D$31=0,"",100-((K9*100)/$D$31)) -> 100 | M9: =IF($D$31=0,"",100-((G9*100)/$D$31)) -> 100
A10: =Listado!A11 -> 8 | B10: =Listado!B11 -> Galán Castro | C10: =Listado!C11 -> Asil | D10: =Listado!E11 -> asil.galan@tajamar365.com | E10: =SUM(Octubre!O11,Noviembre!O11,Diciembre!O11,Enero!O12,Febrero!O11,Marzo!O11,Abril!O11,Mayo!O11,Junio!O11) -> 0 | F10: =IF($D$31=0,"",100-((E10*100)/$D$31)) -> 100 | G10: =SUM(Octubre!Q11,Noviembre!Q11,Diciembre!Q11,Enero!Q12,Febrero!Q11,Marzo!Q11,Abril!Q11,Mayo!Q11,Junio!Q11) -> 0 | H10: =IF($D$31=0,"",100-((I10*100)/$D$31)) -> 100 | I10: =SUM(Octubre!P11,Noviembre!P11,Diciembre!P11,Enero!P12,Febrero!P11,Marzo!P11,Abril!P11,Mayo!P11,Junio!P11) -> 0 | J10: =SUM(Octubre!J11,Octubre!K11,Octubre!M11,Octubre!N11,Noviembre!J11,Noviembre!K11,Noviembre!M11,Noviembre!N11,Diciembre!J11,Diciembre!K11,Diciembre!M11,Diciembre!N11,Enero!J12,Enero!K12,Enero!M12,Enero!N12,Febrero!J11,Febrero!K11,Febrero!M11,Febrero!N11,Marzo!J11,Marzo!K11,Marzo!M11,Marzo!N11,Abril!J11,Abril!K11,Abril!M11,Abril!N11,Mayo!J11,Mayo!K11,Mayo!M11,Mayo!N11,Junio!J11,Junio!K11,Junio!M11,Junio!N11) -> 0 | K10: =(J10/2)+I10 -> 0 | L10: =IF($D$31=0,"",100-((K10*100)/$D$31)) -> 100 | M10: =IF($D$31=0,"",100-((G10*100)/$D$31)) -> 100
A11: =Listado!A12 -> 9 | B11: =Listado!B12 -> García Martín | C11: =Listado!C12 -> Alonso | D11: =Listado!E12 -> alonso.garcia@tajamar365.com | E11: =SUM(Octubre!O12,Noviembre!O12,Diciembre!O12,Enero!O13,Febrero!O12,Marzo!O12,Abril!O12,Mayo!O12,Junio!O12) -> 0 | F11: =IF($D$31=0,"",100-((E11*100)/$D$31)) -> 100 | G11: =SUM(Octubre!Q12,Noviembre!Q12,Diciembre!Q12,Enero!Q13,Febrero!Q12,Marzo!Q12,Abril!Q12,Mayo!Q12,Junio!Q12) -> 0 | H11: =IF($D$31=0,"",100-((I11*100)/$D$31)) -> 100 | I11: =SUM(Octubre!P12,Noviembre!P12,Diciembre!P12,Enero!P13,Febrero!P12,Marzo!P12,Abril!P12,Mayo!P12,Junio!P12) -> 0 | J11: =SUM(Octubre!J12,Octubre!K12,Octubre!M12,Octubre!N12,Noviembre!J12,Noviembre!K12,Noviembre!M12,Noviembre!N12,Diciembre!J12,Diciembre!K12,Diciembre!M12,Diciembre!N12,Enero!J13,Enero!K13,Enero!M13,Enero!N13,Febrero!J12,Febrero!K12,Febrero!M12,Febrero!N12,Marzo!J12,Marzo!K12,Marzo!M12,Marzo!N12,Abril!J12,Abril!K12,Abril!M12,Abril!N12,Mayo!J12,Mayo!K12,Mayo!M12,Mayo!N12,Junio!J12,Junio!K12,Junio!M12,Junio!N12) -> 0 | K11: =(J11/2)+I11 -> 0 | L11: =IF($D$31=0,"",100-((K11*100)/$D$31)) -> 100 | M11: =IF($D$31=0,"",100-((G11*100)/$D$31)) -> 100
A12: =Listado!A13 -> 10 | B12: =Listado!B13 -> García Muñoz | C12: =Listado!C13 -> Raúl | D12: =Listado!E13 -> raul.garciamunoz@tajamar365.com | E12: =SUM(Octubre!O13,Noviembre!O13,Diciembre!O13,Enero!O14,Febrero!O13,Marzo!O13,Abril!O13,Mayo!O13,Junio!O13) -> 0 | F12: =IF($D$31=0,"",100-((E12*100)/$D$31)) -> 100 | G12: =SUM(Octubre!Q13,Noviembre!Q13,Diciembre!Q13,Enero!Q14,Febrero!Q13,Marzo!Q13,Abril!Q13,Mayo!Q13,Junio!Q13) -> 0 | H12: =IF($D$31=0,"",100-((I12*100)/$D$31)) -> 100 | I12: =SUM(Octubre!P13,Noviembre!P13,Diciembre!P13,Enero!P14,Febrero!P13,Marzo!P13,Abril!P13,Mayo!P13,Junio!P13) -> 0 | J12: =SUM(Octubre!J13,Octubre!K13,Octubre!M13,Octubre!N13,Noviembre!J13,Noviembre!K13,Noviembre!M13,Noviembre!N13,Diciembre!J13,Diciembre!K13,Diciembre!M13,Diciembre!N13,Enero!J14,Enero!K14,Enero!M14,Enero!N14,Febrero!J13,Febrero!K13,Febrero!M13,Febrero!N13,Marzo!J13,Marzo!K13,Marzo!M13,Marzo!N13,Abril!J13,Abril!K13,Abril!M13,Abril!N13,Mayo!J13,Mayo!K13,Mayo!M13,Mayo!N13,Junio!J13,Junio!K13,Junio!M13,Junio!N13) -> 0 | K12: =(J12/2)+I12 -> 0 | L12: =IF($D$31=0,"",100-((K12*100)/$D$31)) -> 100 | M12: =IF($D$31=0,"",100-((G12*100)/$D$31)) -> 100
A13: =Listado!A14 -> 11 | B13: =Listado!B14 -> Gil Fuertes | C13: =Listado!C14 -> Héctor | D13: =Listado!E14 -> hector.gil@tajamar365.com | E13: =SUM(Octubre!O14,Noviembre!O14,Diciembre!O14,Enero!O15,Febrero!O14,Marzo!O14,Abril!O14,Mayo!O14,Junio!O14) -> 0 | F13: =IF($D$31=0,"",100-((E13*100)/$D$31)) -> 100 | G13: =SUM(Octubre!Q14,Noviembre!Q14,Diciembre!Q14,Enero!Q15,Febrero!Q14,Marzo!Q14,Abril!Q14,Mayo!Q14,Junio!Q14) -> 0 | H13: =IF($D$31=0,"",100-((I13*100)/$D$31)) -> 100 | I13: =SUM(Octubre!P14,Noviembre!P14,Diciembre!P14,Enero!P15,Febrero!P14,Marzo!P14,Abril!P14,Mayo!P14,Junio!P14) -> 0 | J13: =SUM(Octubre!J14,Octubre!K14,Octubre!M14,Octubre!N14,Noviembre!J14,Noviembre!K14,Noviembre!M14,Noviembre!N14,Diciembre!J14,Diciembre!K14,Diciembre!M14,Diciembre!N14,Enero!J15,Enero!K15,Enero!M15,Enero!N15,Febrero!J14,Febrero!K14,Febrero!M14,Febrero!N14,Marzo!J14,Marzo!K14,Marzo!M14,Marzo!N14,Abril!J14,Abril!K14,Abril!M14,Abril!N14,Mayo!J14,Mayo!K14,Mayo!M14,Mayo!N14,Junio!J14,Junio!K14,Junio!M14,Junio!N14) -> 0 | K13: =(J13/2)+I13 -> 0 | L13: =IF($D$31=0,"",100-((K13*100)/$D$31)) -> 100 | M13: =IF($D$31=0,"",100-((G13*100)/$D$31)) -> 100
A14: =Listado!A15 -> 12 | B14: =Listado!B15 -> Gonzalo Lucas | C14: =Listado!C15 -> Pablo | D14: =Listado!E15 -> pablo.gonzalo@tajamar365.com | E14: =SUM(Octubre!O15,Noviembre!O15,Diciembre!O15,Enero!O16,Febrero!O15,Marzo!O15,Abril!O15,Mayo!O15,Junio!O15) -> 0 | F14: =IF($D$31=0,"",100-((E14*100)/$D$31)) -> 100 | G14: =SUM(Octubre!Q15,Noviembre!Q15,Diciembre!Q15,Enero!Q16,Febrero!Q15,Marzo!Q15,Abril!Q15,Mayo!Q15,Junio!Q15) -> 0 | H14: =IF($D$31=0,"",100-((I14*100)/$D$31)) -> 100 | I14: =SUM(Octubre!P15,Noviembre!P15,Diciembre!P15,Enero!P16,Febrero!P15,Marzo!P15,Abril!P15,Mayo!P15,Junio!P15) -> 0 | J14: =SUM(Octubre!J15,Octubre!K15,Octubre!M15,Octubre!N15,Noviembre!J15,Noviembre!K15,Noviembre!M15,Noviembre!N15,Diciembre!J15,Diciembre!K15,Diciembre!M15,Diciembre!N15,Enero!J16,Enero!K16,Enero!M16,Enero!N16,Febrero!J15,Febrero!K15,Febrero!M15,Febrero!N15,Marzo!J15,Marzo!K15,Marzo!M15,Marzo!N15,Abril!J15,Abril!K15,Abril!M15,Abril!N15,Mayo!J15,Mayo!K15,Mayo!M15,Mayo!N15,Junio!J15,Junio!K15,Junio!M15,Junio!N15) -> 0 | K14: =(J14/2)+I14 -> 0 | L14: =IF($D$31=0,"",100-((K14*100)/$D$31)) -> 100 | M14: =IF($D$31=0,"",100-((G14*100)/$D$31)) -> 100
A15: =Listado!A16 -> 13 | B15: =Listado!B16 -> Jacek | C15: =Listado!C16 -> Adrian | D15: =Listado!E16 -> adrian.jacek@tajamar365.com | E15: =SUM(Octubre!O16,Noviembre!O16,Diciembre!O16,Enero!O17,Febrero!O16,Marzo!O16,Abril!O16,Mayo!O16,Junio!O16) -> 0 | F15: =IF($D$31=0,"",100-((E15*100)/$D$31)) -> 100 | G15: =SUM(Octubre!Q16,Noviembre!Q16,Diciembre!Q16,Enero!Q17,Febrero!Q16,Marzo!Q16,Abril!Q16,Mayo!Q16,Junio!Q16) -> 0 | H15: =IF($D$31=0,"",100-((I15*100)/$D$31)) -> 100 | I15: =SUM(Octubre!P16,Noviembre!P16,Diciembre!P16,Enero!P17,Febrero!P16,Marzo!P16,Abril!P16,Mayo!P16,Junio!P16) -> 0 | J15: =SUM(Octubre!J16,Octubre!K16,Octubre!M16,Octubre!N16,Noviembre!J16,Noviembre!K16,Noviembre!M16,Noviembre!N16,Diciembre!J16,Diciembre!K16,Diciembre!M16,Diciembre!N16,Enero!J17,Enero!K17,Enero!M17,Enero!N17,Febrero!J16,Febrero!K16,Febrero!M16,Febrero!N16,Marzo!J16,Marzo!K16,Marzo!M16,Marzo!N16,Abril!J16,Abril!K16,Abril!M16,Abril!N16,Mayo!J16,Mayo!K16,Mayo!M16,Mayo!N16,Junio!J16,Junio!K16,Junio!M16,Junio!N16) -> 0 | K15: =(J15/2)+I15 -> 0 | L15: =IF($D$31=0,"",100-((K15*100)/$D$31)) -> 100 | M15: =IF($D$31=0,"",100-((G15*100)/$D$31)) -> 100
A16: =Listado!A17 -> 14 | B16: =Listado!B17 -> López Pachón | C16: =Listado!C17 -> José Antonio | D16: =Listado!E17 -> joseantonio.lopez@tajamar365.com | E16: =SUM(Octubre!O17,Noviembre!O17,Diciembre!O17,Enero!O18,Febrero!O17,Marzo!O17,Abril!O17,Mayo!O17,Junio!O17) -> 0 | F16: =IF($D$31=0,"",100-((E16*100)/$D$31)) -> 100 | G16: =SUM(Octubre!Q17,Noviembre!Q17,Diciembre!Q17,Enero!Q18,Febrero!Q17,Marzo!Q17,Abril!Q17,Mayo!Q17,Junio!Q17) -> 0 | H16: =IF($D$31=0,"",100-((I16*100)/$D$31)) -> 100 | I16: =SUM(Octubre!P17,Noviembre!P17,Diciembre!P17,Enero!P18,Febrero!P17,Marzo!P17,Abril!P17,Mayo!P17,Junio!P17) -> 0 | J16: =SUM(Octubre!J17,Octubre!K17,Octubre!M17,Octubre!N17,Noviembre!J17,Noviembre!K17,Noviembre!M17,Noviembre!N17,Diciembre!J17,Diciembre!K17,Diciembre!M17,Diciembre!N17,Enero!J18,Enero!K18,Enero!M18,Enero!N18,Febrero!J17,Febrero!K17,Febrero!M17,Febrero!N17,Marzo!J17,Marzo!K17,Marzo!M17,Marzo!N17,Abril!J17,Abril!K17,Abril!M17,Abril!N17,Mayo!J17,Mayo!K17,Mayo!M17,Mayo!N17,Junio!J17,Junio!K17,Junio!M17,Junio!N17) -> 0 | K16: =(J16/2)+I16 -> 0 | L16: =IF($D$31=0,"",100-((K16*100)/$D$31)) -> 100 | M16: =IF($D$31=0,"",100-((G16*100)/$D$31)) -> 100
A17: =Listado!A18 -> 15 | B17: =Listado!B18 -> Miguel Tolosana | C17: =Listado!C18 -> María | D17: =Listado!E18 -> maria.miguel@tajamar365.com | E17: =SUM(Octubre!O18,Noviembre!O18,Diciembre!O18,Enero!O19,Febrero!O18,Marzo!O18,Abril!O18,Mayo!O18,Junio!O18) -> 0 | F17: =IF($D$31=0,"",100-((E17*100)/$D$31)) -> 100 | G17: =SUM(Octubre!Q18,Noviembre!Q18,Diciembre!Q18,Enero!Q19,Febrero!Q18,Marzo!Q18,Abril!Q18,Mayo!Q18,Junio!Q18) -> 0 | H17: =IF($D$31=0,"",100-((I17*100)/$D$31)) -> 100 | I17: =SUM(Octubre!P18,Noviembre!P18,Diciembre!P18,Enero!P19,Febrero!P18,Marzo!P18,Abril!P18,Mayo!P18,Junio!P18) -> 0 | J17: =SUM(Octubre!J18,Octubre!K18,Octubre!M18,Octubre!N18,Noviembre!J18,Noviembre!K18,Noviembre!M18,Noviembre!N18,Diciembre!J18,Diciembre!K18,Diciembre!M18,Diciembre!N18,Enero!J19,Enero!K19,Enero!M19,Enero!N19,Febrero!J18,Febrero!K18,Febrero!M18,Febrero!N18,Marzo!J18,Marzo!K18,Marzo!M18,Marzo!N18,Abril!J18,Abril!K18,Abril!M18,Abril!N18,Mayo!J18,Mayo!K18,Mayo!M18,Mayo!N18,Junio!J18,Junio!K18,Junio!M18,Junio!N18) -> 0 | K17: =(J17/2)+I17 -> 0 | L17: =IF($D$31=0,"",100-((K17*100)/$D$31)) -> 100 | M17: =IF($D$31=0,"",100-((G17*100)/$D$31)) -> 100
A18: =Listado!A19 -> 16 | B18: =Listado!B19 -> Navarro Fernández | C18: =Listado!C19 -> Alejandro | D18: =Listado!E19 -> alejandro.navarro@tajamar365.com | E18: =SUM(Octubre!O19,Noviembre!O19,Diciembre!O19,Enero!O20,Febrero!O19,Marzo!O19,Abril!O19,Mayo!O19,Junio!O19) -> 0 | F18: =IF($D$31=0,"",100-((E18*100)/$D$31)) -> 100 | G18: =SUM(Octubre!Q19,Noviembre!Q19,Diciembre!Q19,Enero!Q20,Febrero!Q19,Marzo!Q19,Abril!Q19,Mayo!Q19,Junio!Q19) -> 0 | H18: =IF($D$31=0,"",100-((I18*100)/$D$31)) -> 100 | I18: =SUM(Octubre!P19,Noviembre!P19,Diciembre!P19,Enero!P20,Febrero!P19,Marzo!P19,Abril!P19,Mayo!P19,Junio!P19) -> 0 | J18: =SUM(Octubre!J19,Octubre!K19,Octubre!M19,Octubre!N19,Noviembre!J19,Noviembre!K19,Noviembre!M19,Noviembre!N19,Diciembre!J19,Diciembre!K19,Diciembre!M19,Diciembre!N19,Enero!J20,Enero!K20,Enero!M20,Enero!N20,Febrero!J19,Febrero!K19,Febrero!M19,Febrero!N19,Marzo!J19,Marzo!K19,Marzo!M19,Marzo!N19,Abril!J19,Abril!K19,Abril!M19,Abril!N19,Mayo!J19,Mayo!K19,Mayo!M19,Mayo!N19,Junio!J19,Junio!K19,Junio!M19,Junio!N19) -> 0 | K18: =(J18/2)+I18 -> 0 | L18: =IF($D$31=0,"",100-((K18*100)/$D$31)) -> 100 | M18: =IF($D$31=0,"",100-((G18*100)/$D$31)) -> 100
... A28: =Listado!A29 -> 26 | B28: =Listado!B29 -> Vázquez Martínez | C28: =Listado!C29 -> Iván | D28: =Listado!E29 -> ivan.vazquez@tajamar365.com | E28: =SUM(Octubre!O29,Noviembre!O29,Diciembre!O29,Enero!O30,Febrero!O29,Marzo!O29,Abril!O29,Mayo!O29,Junio!O29) -> 0 | F28: =IF($D$31=0,"",100-((E28*100)/$D$31)) -> 100 | G28: =SUM(Octubre!Q29,Noviembre!Q29,Diciembre!Q29,Enero!Q30,Febrero!Q29,Marzo!Q29,Abril!Q29,Mayo!Q29,Junio!Q29) -> 0 | H28: =IF($D$31=0,"",100-((I28*100)/$D$31)) -> 100 | I28: =SUM(Octubre!P29,Noviembre!P29,Diciembre!P29,Enero!P30,Febrero!P29,Marzo!P29,Abril!P29,Mayo!P29,Junio!P29) -> 0 | J28: =SUM(Octubre!J29,Octubre!K29,Octubre!M29,Octubre!N29,Noviembre!J29,Noviembre!K29,Noviembre!M29,Noviembre!N29,Diciembre!J29,Diciembre!K29,Diciembre!M29,Diciembre!N29,Enero!J30,Enero!K30,Enero!M30,Enero!N30,Febrero!J29,Febrero!K29,Febrero!M29,Febrero!N29,Marzo!J29,Marzo!K29,Marzo!M29,Marzo!N29,Abril!J29,Abril!K29,Abril!M29,Abril!N29,Mayo!J29,Mayo!K29,Mayo!M29,Mayo!N29,Junio!J29,Junio!K29,Junio!M29,Junio!N29) -> 0 | K28: =(J28/2)+I28 -> 0 | L28: =IF($D$31=0,"",100-((K28*100)/$D$31)) -> 100 | M28: =IF($D$31=0,"",100-((G28*100)/$D$31)) -> 100
B31: Nº TOTAL DE DÍAS LECTIVOS | D31: =Totales!F29 -> 156

Sheet Equipos encendidos
A1: Fecha | B1: Equipos
A2: 44244 | B2: 4, 7, 9, 10, 22, 26, 27
A3: 44245 | B3: 4, 6, 7, 12, 15, 20, 22, 27
A4: 44250 | B4: 7, 22, 23, 24, 26, 27
A5: 44251 | B5: 2, 4, 7, 13, 22, 23, 27
A6: 44252 | B6: 4, 5, 7, 14, 22, 23, 27
A7: 44253 | B7: 4, 5, 7, 14, 22
A8: 44256 | B8: 2, 7, 22, 27
A9: 44257 | B9: 7, 19, 22, 27
A10: 44258 | B10: 7, 21
A11: 44263 | B11: 7, 18, 22, 25, 27
A12: 44265 | B12: 7, 19, 22, 23, 26
A13: 44267 | B13: 4, 7, 8, 22, 27
... A16: 44277 | B16: 4, 7, 8, 20, 22, 23, 27, 28

Sheet Mayo
A1: hotm | H1: ZONA DE AUTOCÁLCULO | W1: x | X1: x | AC1: x | AD1: x | AE1: x | AK1: x | AL1: x | AS1: NO MODIFICAR
H2: DÍAS | R2: Lunes | S2: Martes | T2: Miércoles | U2: Jueves | V2: Viernes | W2: Sábado | X2: Domingo | Y2: Lunes | Z2: Martes | AA2: Miércoles | AB2: Jueves | AC2: Viernes | AD2: Sábado | AE2: Domingo | AF2: Lunes | AG2: Martes | AH2: Miércoles | AI2: Jueves | AJ2: Viernes | AK2: Sábado | AL2: Domingo | AM2: Lunes | AN2: Martes | AO2: Miércoles | AP2: Jueves | AQ2: Viernes | AS2: HORAS
A3: Nº | B3: APELLIDOS | C3: NOMBRE | D3: Nick name | E3: Email 365 | F3: Email | G3: Teléfono | H3: A | I3: FJ | J3: RJ | K3: SAFJ | L3: F | M3: R | N3: SAF | O3: TOTAL FALTAS MES | P3: Nº de Faltas Total F Mes | Q3: Nº de Faltas Total F y R Mes | R3: 46146 | S3: 46147 | T3: 46148 | U3: 46149 | V3: 46150 | W3: 46151 | X3: 46152 | Y3: 46153 | Z3: 46154 | AA3: 46155 | AB3: 46156 | AC3: 46157 | AD3: 46158 | AE3: 46159 | AF3: 46160 | AG3: 46161 | AH3: 46162 | AI3: 46163 | AJ3: 46164 | AK3: 46165 | AL3: 46166 | AM3: 46167 | AN3: 46168 | AO3: 46169 | AP3: 46170 | AQ3: 46171 | AS3: ASISTENCIA
A4: 1 | B4: =Listado!B4 -> Alonso Mansilla | C4: =Listado!C4 -> Javier | D4: =Listado!D4 -> Javi | E4: =Listado!E4 -> javier.alonsomansilla@tajamar365.com | H4: =COUNTBLANK(R4:AQ4) -> 19 | I4: =COUNTIF(R4:AQ4,"FJ") -> 0 | J4: =COUNTIF(R4:AQ4,"RJ") -> 0 | K4: =COUNTIF(R4:AQ4,"SAFJ") -> 0 | L4: =COUNTIF(R4:AQ4,"F") -> 0 | M4: =COUNTIF(R4:AQ4,"R") -> 0 | N4: =COUNTIF(R4:AQ4,"SAF") -> 0 | O4: =(L4+(M4/2))+(N4/2) -> 0 | P4: =I4+L4 -> 0 | Q4: =SUM(I4:N4) -> 0 | W4: x | X4: x | AC4: x | AD4: x | AE4: x | AK4: x | AL4: x | AS4: =H4*B$49 -> 104.5
A5: 2 | B5: =Listado!B5 -> Barbacid Fernández | C5: =Listado!C5 -> Alberto | D5: =Listado!D5 -> Alberto | E5: =Listado!E5 -> alberto.barbacid@tajamar365.com | H5: =COUNTBLANK(R5:AQ5) -> 19 | I5: =COUNTIF(R5:AQ5,"FJ") -> 0 | J5: =COUNTIF(R5:AQ5,"RJ") -> 0 | K5: =COUNTIF(R5:AQ5,"SAFJ") -> 0 | L5: =COUNTIF(R5:AQ5,"F") -> 0 | M5: =COUNTIF(R5:AQ5,"R") -> 0 | N5: =COUNTIF(R5:AQ5,"SAF") -> 0 | O5: =(L5+(M5/2))+(N5/2) -> 0 | P5: =I5+L5 -> 0 | Q5: =SUM(I5:N5) -> 0 | W5: x | X5: x | AC5: x | AD5: x | AE5: x | AK5: x | AL5: x | AS5: =H5*B$49 -> 104.5
A6: 3 | B6: =Listado!B6 -> Bayas Sarzosa | C6: =Listado!C6 -> Kevin | D6: =Listado!D6 -> Kevin | E6: =Listado!E6 -> kevin.bayas@tajamar365.com | H6: =COUNTBLANK(R6:AQ6) -> 19 | I6: =COUNTIF(R6:AQ6,"FJ") -> 0 | J6: =COUNTIF(R6:AQ6,"RJ") -> 0 | K6: =COUNTIF(R6:AQ6,"SAFJ") -> 0 | L6: =COUNTIF(R6:AQ6,"F") -> 0 | M6: =COUNTIF(R6:AQ6,"R") -> 0 | N6: =COUNTIF(R6:AQ6,"SAF") -> 0 | O6: =(L6+(M6/2))+(N6/2) -> 0 | P6: =I6+L6 -> 0 | Q6: =SUM(I6:N6) -> 0 | W6: x | X6: x | AC6: x | AD6: x | AE6: x | AK6: x | AL6: x | AS6: =H6*B$49 -> 104.5
A7: 4 | B7: =Listado!B7 -> Cánovas López | C7: =Listado!C7 -> Alejandro | D7: =Listado!D7 -> Alex | E7: =Listado!E7 -> alejandro.canovas@tajamar365.com | H7: =COUNTBLANK(R7:AQ7) -> 19 | I7: =COUNTIF(R7:AQ7,"FJ") -> 0 | J7: =COUNTIF(R7:AQ7,"RJ") -> 0 | K7: =COUNTIF(R7:AQ7,"SAFJ") -> 0 | L7: =COUNTIF(R7:AQ7,"F") -> 0 | M7: =COUNTIF(R7:AQ7,"R") -> 0 | N7: =COUNTIF(R7:AQ7,"SAF") -> 0 | O7: =(L7+(M7/2))+(N7/2) -> 0 | P7: =I7+L7 -> 0 | Q7: =SUM(I7:N7) -> 0 | W7: x | X7: x | AC7: x | AD7: x | AE7: x | AK7: x | AL7: x | AS7: =H7*B$49 -> 104.5
A8: 5 | B8: =Listado!B8 -> Cardona Hernández | C8: =Listado!C8 -> Diego | D8: =Listado!D8 -> Diego | E8: =Listado!E8 -> diego.cardona@tajamar365.com | H8: =COUNTBLANK(R8:AQ8) -> 19 | I8: =COUNTIF(R8:AQ8,"FJ") -> 0 | J8: =COUNTIF(R8:AQ8,"RJ") -> 0 | K8: =COUNTIF(R8:AQ8,"SAFJ") -> 0 | L8: =COUNTIF(R8:AQ8,"F") -> 0 | M8: =COUNTIF(R8:AQ8,"R") -> 0 | N8: =COUNTIF(R8:AQ8,"SAF") -> 0 | O8: =(L8+(M8/2))+(N8/2) -> 0 | P8: =I8+L8 -> 0 | Q8: =SUM(I8:N8) -> 0 | W8: x | X8: x | AC8: x | AD8: x | AE8: x | AK8: x | AL8: x | AS8: =H8*B$49 -> 104.5
A9: 6 | B9: =Listado!B9 -> Casco Valero | C9: =Listado!C9 -> Álvaro | D9: =Listado!D9 -> Álvaro | E9: =Listado!E9 -> alvaro.casco@tajamar365.com | H9: =COUNTBLANK(R9:AQ9) -> 19 | I9: =COUNTIF(R9:AQ9,"FJ") -> 0 | J9: =COUNTIF(R9:AQ9,"RJ") -> 0 | K9: =COUNTIF(R9:AQ9,"SAFJ") -> 0 | L9: =COUNTIF(R9:AQ9,"F") -> 0 | M9: =COUNTIF(R9:AQ9,"R") -> 0 | N9: =COUNTIF(R9:AQ9,"SAF") -> 0 | O9: =(L9+(M9/2))+(N9/2) -> 0 | P9: =I9+L9 -> 0 | Q9: =SUM(I9:N9) -> 0 | W9: x | X9: x | AC9: x | AD9: x | AE9: x | AK9: x | AL9: x | AS9: =H9*B$49 -> 104.5
A10: 7 | B10: =Listado!B10 -> Cobo Marcos | C10: =Listado!C10 -> Alejandro | D10: =Listado!D10 -> Alex | E10: =Listado!E10 -> alejandro.cobo@tajamar365.com | H10: =COUNTBLANK(R10:AQ10) -> 19 | I10: =COUNTIF(R10:AQ10,"FJ") -> 0 | J10: =COUNTIF(R10:AQ10,"RJ") -> 0 | K10: =COUNTIF(R10:AQ10,"SAFJ") -> 0 | L10: =COUNTIF(R10:AQ10,"F") -> 0 | M10: =COUNTIF(R10:AQ10,"R") -> 0 | N10: =COUNTIF(R10:AQ10,"SAF") -> 0 | O10: =(L10+(M10/2))+(N10/2) -> 0 | P10: =I10+L10 -> 0 | Q10: =SUM(I10:N10) -> 0 | W10: x | X10: x | AC10: x | AD10: x | AE10: x | AK10: x | AL10: x | AS10: =H10*B$49 -> 104.5
A11: 8 | B11: =Listado!B11 -> Galán Castro | C11: =Listado!C11 -> Asil | D11: =Listado!D11 -> Asil | E11: =Listado!E11 -> asil.galan@tajamar365.com | H11: =COUNTBLANK(R11:AQ11) -> 19 | I11: =COUNTIF(R11:AQ11,"FJ") -> 0 | J11: =COUNTIF(R11:AQ11,"RJ") -> 0 | K11: =COUNTIF(R11:AQ11,"SAFJ") -> 0 | L11: =COUNTIF(R11:AQ11,"F") -> 0 | M11: =COUNTIF(R11:AQ11,"R") -> 0 | N11: =COUNTIF(R11:AQ11,"SAF") -> 0 | O11: =(L11+(M11/2))+(N11/2) -> 0 | P11: =I11+L11 -> 0 | Q11: =SUM(I11:N11) -> 0 | W11: x | X11: x | AC11: x | AD11: x | AE11: x | AK11: x | AL11: x | AS11: =H11*B$49 -> 104.5
A12: 9 | B12: =Listado!B12 -> García Martín | C12: =Listado!C12 -> Alonso | D12: =Listado!D12 -> Alonso | E12: =Listado!E12 -> alonso.garcia@tajamar365.com | H12: =COUNTBLANK(R12:AQ12) -> 19 | I12: =COUNTIF(R12:AQ12,"FJ") -> 0 | J12: =COUNTIF(R12:AQ12,"RJ") -> 0 | K12: =COUNTIF(R12:AQ12,"SAFJ") -> 0 | L12: =COUNTIF(R12:AQ12,"F") -> 0 | M12: =COUNTIF(R12:AQ12,"R") -> 0 | N12: =COUNTIF(R12:AQ12,"SAF") -> 0 | O12: =(L12+(M12/2))+(N12/2) -> 0 | P12: =I12+L12 -> 0 | Q12: =SUM(I12:N12) -> 0 | W12: x | X12: x | AC12: x | AD12: x | AE12: x | AK12: x | AL12: x | AS12: =H12*B$49 -> 104.5
A13: 10 | B13: =Listado!B13 -> García Muñoz | C13: =Listado!C13 -> Raúl | D13: =Listado!D13 -> Raúl | E13: =Listado!E13 -> raul.garciamunoz@tajamar365.com | H13: =COUNTBLANK(R13:AQ13) -> 19 | I13: =COUNTIF(R13:AQ13,"FJ") -> 0 | J13: =COUNTIF(R13:AQ13,"RJ") -> 0 | K13: =COUNTIF(R13:AQ13,"SAFJ") -> 0 | L13: =COUNTIF(R13:AQ13,"F") -> 0 | M13: =COUNTIF(R13:AQ13,"R") -> 0 | N13: =COUNTIF(R13:AQ13,"SAF") -> 0 | O13: =(L13+(M13/2))+(N13/2) -> 0 | P13: =I13+L13 -> 0 | Q13: =SUM(I13:N13) -> 0 | W13: x | X13: x | AC13: x | AD13: x | AE13: x | AK13: x | AL13: x | AS13: =H13*B$49 -> 104.5
A14: 11 | B14: =Listado!B14 -> Gil Fuertes | C14: =Listado!C14 -> Héctor | D14: =Listado!D14 -> Héctor | E14: =Listado!E14 -> hector.gil@tajamar365.com | H14: =COUNTBLANK(R14:AQ14) -> 19 | I14: =COUNTIF(R14:AQ14,"FJ") -> 0 | J14: =COUNTIF(R14:AQ14,"RJ") -> 0 | K14: =COUNTIF(R14:AQ14,"SAFJ") -> 0 | L14: =COUNTIF(R14:AQ14,"F") -> 0 | M14: =COUNTIF(R14:AQ14,"R") -> 0 | N14: =COUNTIF(R14:AQ14,"SAF") -> 0 | O14: =(L14+(M14/2))+(N14/2) -> 0 | P14: =I14+L14 -> 0 | Q14: =SUM(I14:N14) -> 0 | W14: x | X14: x | AC14: x | AD14: x | AE14: x | AK14: x | AL14: x | AS14: =H14*B$49 -> 104.5
A15: 12 | B15: =Listado!B15 -> Gonzalo Lucas | C15: =Listado!C15 -> Pablo | D15: =Listado!D15 -> Pablo | E15: =Listado!E15 -> pablo.gonzalo@tajamar365.com | H15: =COUNTBLANK(R15:AQ15) -> 19 | I15: =COUNTIF(R15:AQ15,"FJ") -> 0 | J15: =COUNTIF(R15:AQ15,"RJ") -> 0 | K15: =COUNTIF(R15:AQ15,"SAFJ") -> 0 | L15: =COUNTIF(R15:AQ15,"F") -> 0 | M15: =COUNTIF(R15:AQ15,"R") -> 0 | N15: =COUNTIF(R15:AQ15,"SAF") -> 0 | O15: =(L15+(M15/2))+(N15/2) -> 0 | P15: =I15+L15 -> 0 | Q15: =SUM(I15:N15) -> 0 | W15: x | X15: x | AC15: x | AD15: x | AE15: x | AK15: x | AL15: x | AS15: =H15*B$49 -> 104.5
... A29: 26 | B29: =Listado!B29 -> Vázquez Martínez | C29: =Listado!C29 -> Iván | D29: =Listado!D29 -> Iván | E29: =Listado!E29 -> ivan.vazquez@tajamar365.com | H29: =COUNTBLANK(R29:AQ29) -> 19 | I29: =COUNTIF(R29:AQ29,"FJ") -> 0 | J29: =COUNTIF(R29:AQ29,"RJ") -> 0 | K29: =COUNTIF(R29:AQ29,"SAFJ") -> 0 | L29: =COUNTIF(R29:AQ29,"F") -> 0 | M29: =COUNTIF(R29:AQ29,"R") -> 0 | N29: =COUNTIF(R29:AQ29,"SAF") -> 0 | O29: =(L29+(M29/2))+(N29/2) -> 0 | P29: =I29+L29 -> 0 | Q29: =SUM(I29:N29) -> 0 | W29: x | X29: x | AC29: x | AD29: x | AE29: x | AK29: x | AL29: x | AS29: =H29*B$49 -> 104.5
H31: CLAVE PROFESOR (INICIALES):
H32: CLAVE COORDINADOR (JBB):
A33: CLAVES (escribir en mayúsculas)
A34: ASISTENCIA | C34: Dejar en blanco
A35: PRESENTACIÓN PROYECTO EN CASA | B35: PPC
A36: FALTA JUSTIFICADA | B36: FJ | C36: (aporta justificante original válido)
A37: RETRASO JUSTIFICADO | B37: RJ | C37: (aporta justificante original válido) | G37: INSERTAR COMENTARIOS PARA ESPECIFICAR A QUÉ HORA LLEGA TARDE UN ALUMNO O A QUÉ HORA SE MARCHA UN ALUMNO
A38: SALIDA ANTES DE FINALIZAR JUSTIFICADA | B38: SAFJ | C38: (aporta justificante original válido)
A39: FALTA | B39: F | C39: (si falta más del 50% de la jornada, computar como falta)
A40: RETRASO | B40: R | C40: (si no está al comienzo de la clase. Se considera retraso si se incorpora justo después del descanso, a las 12:00
A41: SALIDA ANTES DE FINALIZAR CLASE | B41: SAF | C41: (si no está al finalizar la clase). Si se marcha a partir de la mitad de la jornada
A42: NO SE HA INCORPORADO TODAVÍA | B42: X
A43: CLAVE PROFESOR | B43: Escribir iniciales | C43: Sobre fondo de color verde
A47: NO MODIFICAR
A48: DÍAS LECTIVOS MES: | B48: =COUNTBLANK(R1:AQ1) -> 19 | C48: se autocalcula
A49: HORAS DÍA: | B49: 5.5
A50: HORAS LECTIVAS MES: | B50: =B48*B49 -> 104.5 | C50: OBSERVACIONES (si hay días con menos de X horas lectivas, poner el nº de horas lectivas al mes a mano)
A52: TOTAL HORAS CURSO: | B52: =[1]Septiembre!B50 -> 951.5

Sheet Abril
A1: hotm | H1: ZONA DE AUTOCÁLCULO | V1: x | W1: x | AC1: x | AD1: x | AJ1: x | AK1: x | AQ1: NO MODIFICAR
H2: DÍAS | R2: Martes | S2: Miércoles | T2: Jueves | U2: Viernes | V2: Sábado | W2: Domingo | X2: Lunes | Y2: Martes | Z2: Miércoles | AA2: Jueves | AB2: Viernes | AC2: Sábado | AD2: Domingo | AE2: Lunes | AF2: Martes | AG2: Miércoles | AH2: Jueves | AI2: Viernes | AJ2: Sábado | AK2: Domingo | AL2: Lunes | AM2: Martes | AN2: Miércoles | AO2: Jueves | AQ2: HORAS
A3: Nº | B3: APELLIDOS | C3: NOMBRE | D3: Nick name | E3: Email 365 | F3: Email | G3: Teléfono | H3: A | I3: FJ | J3: RJ | K3: SAFJ | L3: F | M3: R | N3: SAF | O3: TOTAL FALTAS MES | P3: Nº de Faltas Total F Mes | Q3: Nº de Faltas Total F y R Mes | R3: 46119 | S3: 46120 | T3: 46121 | U3: 46122 | V3: 46123 | W3: 46124 | X3: 46125 | Y3: 46126 | Z3: 46127 | AA3: 46128 | AB3: 46129 | AC3: 46130 | AD3: 46131 | AE3: 46132 | AF3: 46133 | AG3: 46134 | AH3: 46135 | AI3: 46136 | AJ3: 46137 | AK3: 46138 | AL3: 46139 | AM3: 46140 | AN3: 46141 | AO3: 46142 | AQ3: ASISTENCIA
A4: 1 | B4: =Listado!B4 -> Alonso Mansilla | C4: =Listado!C4 -> Javier | D4: =Listado!D4 -> Javi | E4: =Listado!E4 -> javier.alonsomansilla@tajamar365.com | H4: =COUNTBLANK(R4:AO4) -> 18 | I4: =COUNTIF(R4:AO4,"FJ") -> 0 | J4: =COUNTIF(R4:AO4,"RJ") -> 0 | K4: =COUNTIF(R4:AO4,"SAFJ") -> 0 | L4: =COUNTIF(R4:AO4,"F") -> 0 | M4: =COUNTIF(R4:AO4,"R") -> 0 | N4: =COUNTIF(R4:AO4,"SAF") -> 0 | O4: =(L4+(M4/2))+(N4/2) -> 0 | P4: =I4+L4 -> 0 | Q4: =SUM(I4:N4) -> 0 | V4: x | W4: x | AC4: x | AD4: x | AJ4: x | AK4: x | AQ4: =H4*B$49 -> 99
A5: 2 | B5: =Listado!B5 -> Barbacid Fernández | C5: =Listado!C5 -> Alberto | D5: =Listado!D5 -> Alberto | E5: =Listado!E5 -> alberto.barbacid@tajamar365.com | H5: =COUNTBLANK(R5:AO5) -> 18 | I5: =COUNTIF(R5:AO5,"FJ") -> 0 | J5: =COUNTIF(R5:AO5,"RJ") -> 0 | K5: =COUNTIF(R5:AO5,"SAFJ") -> 0 | L5: =COUNTIF(R5:AO5,"F") -> 0 | M5: =COUNTIF(R5:AO5,"R") -> 0 | N5: =COUNTIF(R5:AO5,"SAF") -> 0 | O5: =(L5+(M5/2))+(N5/2) -> 0 | P5: =I5+L5 -> 0 | Q5: =SUM(I5:N5) -> 0 | V5: x | W5: x | AC5: x | AD5: x | AJ5: x | AK5: x | AQ5: =H5*B$49 -> 99
A6: 3 | B6: =Listado!B6 -> Bayas Sarzosa | C6: =Listado!C6 -> Kevin | D6: =Listado!D6 -> Kevin | E6: =Listado!E6 -> kevin.bayas@tajamar365.com | H6: =COUNTBLANK(R6:AO6) -> 18 | I6: =COUNTIF(R6:AO6,"FJ") -> 0 | J6: =COUNTIF(R6:AO6,"RJ") -> 0 | K6: =COUNTIF(R6:AO6,"SAFJ") -> 0 | L6: =COUNTIF(R6:AO6,"F") -> 0 | M6: =COUNTIF(R6:AO6,"R") -> 0 | N6: =COUNTIF(R6:AO6,"SAF") -> 0 | O6: =(L6+(M6/2))+(N6/2) -> 0 | P6: =I6+L6 -> 0 | Q6: =SUM(I6:N6) -> 0 | V6: x | W6: x | AC6: x | AD6: x | AJ6: x | AK6: x | AQ6: =H6*B$49 -> 99
A7: 4 | B7: =Listado!B7 -> Cánovas López | C7: =Listado!C7 -> Alejandro | D7: =Listado!D7 -> Alex | E7: =Listado!E7 -> alejandro.canovas@tajamar365.com | H7: =COUNTBLANK(R7:AO7) -> 18 | I7: =COUNTIF(R7:AO7,"FJ") -> 0 | J7: =COUNTIF(R7:AO7,"RJ") -> 0 | K7: =COUNTIF(R7:AO7,"SAFJ") -> 0 | L7: =COUNTIF(R7:AO7,"F") -> 0 | M7: =COUNTIF(R7:AO7,"R") -> 0 | N7: =COUNTIF(R7:AO7,"SAF") -> 0 | O7: =(L7+(M7/2))+(N7/2) -> 0 | P7: =I7+L7 -> 0 | Q7: =SUM(I7:N7) -> 0 | V7: x | W7: x | AC7: x | AD7: x | AJ7: x | AK7: x | AQ7: =H7*B$49 -> 99
A8: 5 | B8: =Listado!B8 -> Cardona Hernández | C8: =Listado!C8 -> Diego | D8: =Listado!D8 -> Diego | E8: =Listado!E8 -> diego.cardona@tajamar365.com | H8: =COUNTBLANK(R8:AO8) -> 18 | I8: =COUNTIF(R8:AO8,"FJ") -> 0 | J8: =COUNTIF(R8:AO8,"RJ") -> 0 | K8: =COUNTIF(R8:AO8,"SAFJ") -> 0 | L8: =COUNTIF(R8:AO8,"F") -> 0 | M8: =COUNTIF(R8:AO8,"R") -> 0 | N8: =COUNTIF(R8:AO8,"SAF") -> 0 | O8: =(L8+(M8/2))+(N8/2) -> 0 | P8: =I8+L8 -> 0 | Q8: =SUM(I8:N8) -> 0 | V8: x | W8: x | AC8: x | AD8: x | AJ8: x | AK8: x | AQ8: =H8*B$49 -> 99
A9: 6 | B9: =Listado!B9 -> Casco Valero | C9: =Listado!C9 -> Álvaro | D9: =Listado!D9 -> Álvaro | E9: =Listado!E9 -> alvaro.casco@tajamar365.com | H9: =COUNTBLANK(R9:AO9) -> 18 | I9: =COUNTIF(R9:AO9,"FJ") -> 0 | J9: =COUNTIF(R9:AO9,"RJ") -> 0 | K9: =COUNTIF(R9:AO9,"SAFJ") -> 0 | L9: =COUNTIF(R9:AO9,"F") -> 0 | M9: =COUNTIF(R9:AO9,"R") -> 0 | N9: =COUNTIF(R9:AO9,"SAF") -> 0 | O9: =(L9+(M9/2))+(N9/2) -> 0 | P9: =I9+L9 -> 0 | Q9: =SUM(I9:N9) -> 0 | V9: x | W9: x | AC9: x | AD9: x | AJ9: x | AK9: x | AQ9: =H9*B$49 -> 99
A10: 7 | B10: =Listado!B10 -> Cobo Marcos | C10: =Listado!C10 -> Alejandro | D10: =Listado!D10 -> Alex | E10: =Listado!E10 -> alejandro.cobo@tajamar365.com | H10: =COUNTBLANK(R10:AO10) -> 18 | I10: =COUNTIF(R10:AO10,"FJ") -> 0 | J10: =COUNTIF(R10:AO10,"RJ") -> 0 | K10: =COUNTIF(R10:AO10,"SAFJ") -> 0 | L10: =COUNTIF(R10:AO10,"F") -> 0 | M10: =COUNTIF(R10:AO10,"R") -> 0 | N10: =COUNTIF(R10:AO10,"SAF") -> 0 | O10: =(L10+(M10/2))+(N10/2) -> 0 | P10: =I10+L10 -> 0 | Q10: =SUM(I10:N10) -> 0 | V10: x | W10: x | AC10: x | AD10: x | AJ10: x | AK10: x | AQ10: =H10*B$49 -> 99
A11: 8 | B11: =Listado!B11 -> Galán Castro | C11: =Listado!C11 -> Asil | D11: =Listado!D11 -> Asil | E11: =Listado!E11 -> asil.galan@tajamar365.com | H11: =COUNTBLANK(R11:AO11) -> 18 | I11: =COUNTIF(R11:AO11,"FJ") -> 0 | J11: =COUNTIF(R11:AO11,"RJ") -> 0 | K11: =COUNTIF(R11:AO11,"SAFJ") -> 0 | L11: =COUNTIF(R11:AO11,"F") -> 0 | M11: =COUNTIF(R11:AO11,"R") -> 0 | N11: =COUNTIF(R11:AO11,"SAF") -> 0 | O11: =(L11+(M11/2))+(N11/2) -> 0 | P11: =I11+L11 -> 0 | Q11: =SUM(I11:N11) -> 0 | V11: x | W11: x | AC11: x | AD11: x | AJ11: x | AK11: x | AQ11: =H11*B$49 -> 99
A12: 9 | B12: =Listado!B12 -> García Martín | C12: =Listado!C12 -> Alonso | D12: =Listado!D12 -> Alonso | E12: =Listado!E12 -> alonso.garcia@tajamar365.com | H12: =COUNTBLANK(R12:AO12) -> 18 | I12: =COUNTIF(R12:AO12,"FJ") -> 0 | J12: =COUNTIF(R12:AO12,"RJ") -> 0 | K12: =COUNTIF(R12:AO12,"SAFJ") -> 0 | L12: =COUNTIF(R12:AO12,"F") -> 0 | M12: =COUNTIF(R12:AO12,"R") -> 0 | N12: =COUNTIF(R12:AO12,"SAF") -> 0 | O12: =(L12+(M12/2))+(N12/2) -> 0 | P12: =I12+L12 -> 0 | Q12: =SUM(I12:N12) -> 0 | V12: x | W12: x | AC12: x | AD12: x | AJ12: x | AK12: x | AQ12: =H12*B$49 -> 99
A13: 10 | B13: =Listado!B13 -> García Muñoz | C13: =Listado!C13 -> Raúl | D13: =Listado!D13 -> Raúl | E13: =Listado!E13 -> raul.garciamunoz@tajamar365.com | H13: =COUNTBLANK(R13:AO13) -> 18 | I13: =COUNTIF(R13:AO13,"FJ") -> 0 | J13: =COUNTIF(R13:AO13,"RJ") -> 0 | K13: =COUNTIF(R13:AO13,"SAFJ") -> 0 | L13: =COUNTIF(R13:AO13,"F") -> 0 | M13: =COUNTIF(R13:AO13,"R") -> 0 | N13: =COUNTIF(R13:AO13,"SAF") -> 0 | O13: =(L13+(M13/2))+(N13/2) -> 0 | P13: =I13+L13 -> 0 | Q13: =SUM(I13:N13) -> 0 | V13: x | W13: x | AC13: x | AD13: x | AJ13: x | AK13: x | AQ13: =H13*B$49 -> 99
A14: 11 | B14: =Listado!B14 -> Gil Fuertes | C14: =Listado!C14 -> Héctor | D14: =Listado!D14 -> Héctor | E14: =Listado!E14 -> hector.gil@tajamar365.com | H14: =COUNTBLANK(R14:AO14) -> 18 | I14: =COUNTIF(R14:AO14,"FJ") -> 0 | J14: =COUNTIF(R14:AO14,"RJ") -> 0 | K14: =COUNTIF(R14:AO14,"SAFJ") -> 0 | L14: =COUNTIF(R14:AO14,"F") -> 0 | M14: =COUNTIF(R14:AO14,"R") -> 0 | N14: =COUNTIF(R14:AO14,"SAF") -> 0 | O14: =(L14+(M14/2))+(N14/2) -> 0 | P14: =I14+L14 -> 0 | Q14: =SUM(I14:N14) -> 0 | V14: x | W14: x | AC14: x | AD14: x | AJ14: x | AK14: x | AQ14: =H14*B$49 -> 99
A15: 12 | B15: =Listado!B15 -> Gonzalo Lucas | C15: =Listado!C15 -> Pablo | D15: =Listado!D15 -> Pablo | E15: =Listado!E15 -> pablo.gonzalo@tajamar365.com | H15: =COUNTBLANK(R15:AO15) -> 18 | I15: =COUNTIF(R15:AO15,"FJ") -> 0 | J15: =COUNTIF(R15:AO15,"RJ") -> 0 | K15: =COUNTIF(R15:AO15,"SAFJ") -> 0 | L15: =COUNTIF(R15:AO15,"F") -> 0 | M15: =COUNTIF(R15:AO15,"R") -> 0 | N15: =COUNTIF(R15:AO15,"SAF") -> 0 | O15: =(L15+(M15/2))+(N15/2) -> 0 | P15: =I15+L15 -> 0 | Q15: =SUM(I15:N15) -> 0 | V15: x | W15: x | AC15: x | AD15: x | AJ15: x | AK15: x | AQ15: =H15*B$49 -> 99
... A29: 26 | B29: =Listado!B29 -> Vázquez Martínez | C29: =Listado!C29 -> Iván | D29: =Listado!D29 -> Iván | E29: =Listado!E29 -> ivan.vazquez@tajamar365.com | H29: =COUNTBLANK(R29:AO29) -> 18 | I29: =COUNTIF(R29:AO29,"FJ") -> 0 | J29: =COUNTIF(R29:AO29,"RJ") -> 0 | K29: =COUNTIF(R29:AO29,"SAFJ") -> 0 | L29: =COUNTIF(R29:AO29,"F") -> 0 | M29: =COUNTIF(R29:AO29,"R") -> 0 | N29: =COUNTIF(R29:AO29,"SAF") -> 0 | O29: =(L29+(M29/2))+(N29/2) -> 0 | P29: =I29+L29 -> 0 | Q29: =SUM(I29:N29) -> 0 | V29: x | W29: x | AC29: x | AD29: x | AJ29: x | AK29: x | AQ29: =H29*B$49 -> 99
H31: CLAVE PROFESOR (INICIALES):
H32: CLAVE COORDINADOR (JBB):
A33: CLAVES (escribir en mayúsculas)
A34: ASISTENCIA | C34: Dejar en blanco
A35: PRESENTACIÓN PROYECTO EN CASA | B35: PPC
A36: FALTA JUSTIFICADA | B36: FJ | C36: (aporta justificante original válido)
A37: RETRASO JUSTIFICADO | B37: RJ | C37: (aporta justificante original válido) | G37: INSERTAR COMENTARIOS PARA ESPECIFICAR A QUÉ HORA LLEGA TARDE UN ALUMNO O A QUÉ HORA SE MARCHA UN ALUMNO
A38: SALIDA ANTES DE FINALIZAR JUSTIFICADA | B38: SAFJ | C38: (aporta justificante original válido)
A39: FALTA | B39: F | C39: (si falta más del 50% de la jornada, computar como falta)
A40: RETRASO | B40: R | C40: (si no está al comienzo de la clase. Se considera retraso si se incorpora justo después del descanso, a las 12:00
A41: SALIDA ANTES DE FINALIZAR CLASE | B41: SAF | C41: (si no está al finalizar la clase). Si se marcha a partir de la mitad de la jornada
A42: NO SE HA INCORPORADO TODAVÍA | B42: X
A43: CLAVE PROFESOR | B43: Escribir iniciales | C43: Sobre fondo de color verde
A47: NO MODIFICAR
A48: DÍAS LECTIVOS MES: | B48: =COUNTBLANK(R1:AO1) -> 18 | C48: se autocalcula
A49: HORAS DÍA: | B49: 5.5
A50: HORAS LECTIVAS MES: | B50: =B48*B49 -> 99 | C50: OBSERVACIONES (si hay días con menos de X horas lectivas, poner el nº de horas lectivas al mes a mano)
A52: TOTAL HORAS CURSO: | B52: =[1]Septiembre!B50 -> 951.5

Sheet Marzo
A1: hotm | H1: ZONA DE AUTOCÁLCULO | V1: x | W1: x | AC1: x | AD1: x | AJ1: x | AK1: x | AQ1: NO MODIFICAR
H2: DÍAS | R2: Martes | S2: Miércoles | T2: Jueves | U2: Viernes | V2: Sábado | W2: Domingo | X2: Lunes | Y2: Martes | Z2: Miércoles | AA2: Jueves | AB2: Viernes | AC2: Sábado | AD2: Domingo | AE2: Lunes | AF2: Martes | AG2: Miércoles | AH2: Jueves | AI2: Viernes | AJ2: Sábado | AK2: Domingo | AL2: Lunes | AM2: Martes | AN2: Miércoles | AO2: Jueves | AQ2: HORAS
A3: Nº | B3: APELLIDOS | C3: NOMBRE | D3: Nick name | E3: Email 365 | F3: Email | G3: Teléfono | H3: A | I3: FJ | J3: RJ | K3: SAFJ | L3: F | M3: R | N3: SAF | O3: TOTAL FALTAS MES | P3: Nº de Faltas Total F Mes | Q3: Nº de Faltas Total F y R Mes | R3: 46084 | S3: 46085 | T3: 46086 | U3: 46087 | V3: 46088 | W3: 46089 | X3: 46090 | Y3: 46091 | Z3: 46092 | AA3: 46093 | AB3: 46094 | AC3: 46095 | AD3: 46096 | AE3: 46097 | AF3: 46098 | AG3: 46099 | AH3: 46100 | AI3: 46101 | AJ3: 46102 | AK3: 46103 | AL3: 46104 | AM3: 46105 | AN3: 46106 | AO3: 46107 | AQ3: ASISTENCIA
A4: 1 | B4: =Listado!B4 -> Alonso Mansilla | C4: =Listado!C4 -> Javier | D4: =Listado!D4 -> Javi | E4: =Listado!E4 -> javier.alonsomansilla@tajamar365.com | H4: =COUNTBLANK(R4:AO4) -> 18 | I4: =COUNTIF(R4:AO4,"FJ") -> 0 | J4: =COUNTIF(R4:AO4,"RJ") -> 0 | K4: =COUNTIF(R4:AO4,"SAFJ") -> 0 | L4: =COUNTIF(R4:AO4,"F") -> 0 | M4: =COUNTIF(R4:AO4,"R") -> 0 | N4: =COUNTIF(R4:AO4,"SAF") -> 0 | O4: =(L4+(M4/2))+(N4/2) -> 0 | P4: =I4+L4 -> 0 | Q4: =SUM(I4:N4) -> 0 | V4: x | W4: x | AC4: x | AD4: x | AJ4: x | AK4: x | AQ4: =H4*B$49 -> 99
A5: 2 | B5: =Listado!B5 -> Barbacid Fernández | C5: =Listado!C5 -> Alberto | D5: =Listado!D5 -> Alberto | E5: =Listado!E5 -> alberto.barbacid@tajamar365.com | H5: =COUNTBLANK(R5:AO5) -> 18 | I5: =COUNTIF(R5:AO5,"FJ") -> 0 | J5: =COUNTIF(R5:AO5,"RJ") -> 0 | K5: =COUNTIF(R5:AO5,"SAFJ") -> 0 | L5: =COUNTIF(R5:AO5,"F") -> 0 | M5: =COUNTIF(R5:AO5,"R") -> 0 | N5: =COUNTIF(R5:AO5,"SAF") -> 0 | O5: =(L5+(M5/2))+(N5/2) -> 0 | P5: =I5+L5 -> 0 | Q5: =SUM(I5:N5) -> 0 | V5: x | W5: x | AC5: x | AD5: x | AJ5: x | AK5: x | AQ5: =H5*B$49 -> 99
A6: 3 | B6: =Listado!B6 -> Bayas Sarzosa | C6: =Listado!C6 -> Kevin | D6: =Listado!D6 -> Kevin | E6: =Listado!E6 -> kevin.bayas@tajamar365.com | H6: =COUNTBLANK(R6:AO6) -> 18 | I6: =COUNTIF(R6:AO6,"FJ") -> 0 | J6: =COUNTIF(R6:AO6,"RJ") -> 0 | K6: =COUNTIF(R6:AO6,"SAFJ") -> 0 | L6: =COUNTIF(R6:AO6,"F") -> 0 | M6: =COUNTIF(R6:AO6,"R") -> 0 | N6: =COUNTIF(R6:AO6,"SAF") -> 0 | O6: =(L6+(M6/2))+(N6/2) -> 0 | P6: =I6+L6 -> 0 | Q6: =SUM(I6:N6) -> 0 | V6: x | W6: x | AC6: x | AD6: x | AJ6: x | AK6: x | AQ6: =H6*B$49 -> 99
A7: 4 | B7: =Listado!B7 -> Cánovas López | C7: =Listado!C7 -> Alejandro | D7: =Listado!D7 -> Alex | E7: =Listado!E7 -> alejandro.canovas@tajamar365.com | H7: =COUNTBLANK(R7:AO7) -> 18 | I7: =COUNTIF(R7:AO7,"FJ") -> 0 | J7: =COUNTIF(R7:AO7,"RJ") -> 0 | K7: =COUNTIF(R7:AO7,"SAFJ") -> 0 | L7: =COUNTIF(R7:AO7,"F") -> 0 | M7: =COUNTIF(R7:AO7,"R") -> 0 | N7: =COUNTIF(R7:AO7,"SAF") -> 0 | O7: =(L7+(M7/2))+(N7/2) -> 0 | P7: =I7+L7 -> 0 | Q7: =SUM(I7:N7) -> 0 | V7: x | W7: x | AC7: x | AD7: x | AJ7: x | AK7: x | AQ7: =H7*B$49 -> 99
A8: 5 | B8: =Listado!B8 -> Cardona Hernández | C8: =Listado!C8 -> Diego | D8: =Listado!D8 -> Diego | E8: =Listado!E8 -> diego.cardona@tajamar365.com | H8: =COUNTBLANK(R8:AO8) -> 18 | I8: =COUNTIF(R8:AO8,"FJ") -> 0 | J8: =COUNTIF(R8:AO8,"RJ") -> 0 | K8: =COUNTIF(R8:AO8,"SAFJ") -> 0 | L8: =COUNTIF(R8:AO8,"F") -> 0 | M8: =COUNTIF(R8:AO8,"R") -> 0 | N8: =COUNTIF(R8:AO8,"SAF") -> 0 | O8: =(L8+(M8/2))+(N8/2) -> 0 | P8: =I8+L8 -> 0 | Q8: =SUM(I8:N8) -> 0 | V8: x | W8: x | AC8: x | AD8: x | AJ8: x | AK8: x | AQ8: =H8*B$49 -> 99
A9: 6 | B9: =Listado!B9 -> Casco Valero | C9: =Listado!C9 -> Álvaro | D9: =Listado!D9 -> Álvaro | E9: =Listado!E9 -> alvaro.casco@tajamar365.com | H9: =COUNTBLANK(R9:AO9) -> 18 | I9: =COUNTIF(R9:AO9,"FJ") -> 0 | J9: =COUNTIF(R9:AO9,"RJ") -> 0 | K9: =COUNTIF(R9:AO9,"SAFJ") -> 0 | L9: =COUNTIF(R9:AO9,"F") -> 0 | M9: =COUNTIF(R9:AO9,"R") -> 0 | N9: =COUNTIF(R9:AO9,"SAF") -> 0 | O9: =(L9+(M9/2))+(N9/2) -> 0 | P9: =I9+L9 -> 0 | Q9: =SUM(I9:N9) -> 0 | V9: x | W9: x | AC9: x | AD9: x | AJ9: x | AK9: x | AQ9: =H9*B$49 -> 99
A10: 7 | B10: =Listado!B10 -> Cobo Marcos | C10: =Listado!C10 -> Alejandro | D10: =Listado!D10 -> Alex | E10: =Listado!E10 -> alejandro.cobo@tajamar365.com | H10: =COUNTBLANK(R10:AO10) -> 18 | I10: =COUNTIF(R10:AO10,"FJ") -> 0 | J10: =COUNTIF(R10:AO10,"RJ") -> 0 | K10: =COUNTIF(R10:AO10,"SAFJ") -> 0 | L10: =COUNTIF(R10:AO10,"F") -> 0 | M10: =COUNTIF(R10:AO10,"R") -> 0 | N10: =COUNTIF(R10:AO10,"SAF") -> 0 | O10: =(L10+(M10/2))+(N10/2) -> 0 | P10: =I10+L10 -> 0 | Q10: =SUM(I10:N10) -> 0 | V10: x | W10: x | AC10: x | AD10: x | AJ10: x | AK10: x | AQ10: =H10*B$49 -> 99
A11: 8 | B11: =Listado!B11 -> Galán Castro | C11: =Listado!C11 -> Asil | D11: =Listado!D11 -> Asil | E11: =Listado!E11 -> asil.galan@tajamar365.com | H11: =COUNTBLANK(R11:AO11) -> 18 | I11: =COUNTIF(R11:AO11,"FJ") -> 0 | J11: =COUNTIF(R11:AO11,"RJ") -> 0 | K11: =COUNTIF(R11:AO11,"SAFJ") -> 0 | L11: =COUNTIF(R11:AO11,"F") -> 0 | M11: =COUNTIF(R11:AO11,"R") -> 0 | N11: =COUNTIF(R11:AO11,"SAF") -> 0 | O11: =(L11+(M11/2))+(N11/2) -> 0 | P11: =I11+L11 -> 0 | Q11: =SUM(I11:N11) -> 0 | V11: x | W11: x | AC11: x | AD11: x | AJ11: x | AK11: x | AQ11: =H11*B$49 -> 99
A12: 9 | B12: =Listado!B12 -> García Martín | C12: =Listado!C12 -> Alonso | D12: =Listado!D12 -> Alonso | E12: =Listado!E12 -> alonso.garcia@tajamar365.com | H12: =COUNTBLANK(R12:AO12) -> 18 | I12: =COUNTIF(R12:AO12,"FJ") -> 0 | J12: =COUNTIF(R12:AO12,"RJ") -> 0 | K12: =COUNTIF(R12:AO12,"SAFJ") -> 0 | L12: =COUNTIF(R12:AO12,"F") -> 0 | M12: =COUNTIF(R12:AO12,"R") -> 0 | N12: =COUNTIF(R12:AO12,"SAF") -> 0 | O12: =(L12+(M12/2))+(N12/2) -> 0 | P12: =I12+L12 -> 0 | Q12: =SUM(I12:N12) -> 0 | V12: x | W12: x | AC12: x | AD12: x | AJ12: x | AK12: x | AQ12: =H12*B$49 -> 99
A13: 10 | B13: =Listado!B13 -> García Muñoz | C13: =Listado!C13 -> Raúl | D13: =Listado!D13 -> Raúl | E13: =Listado!E13 -> raul.garciamunoz@tajamar365.com | H13: =COUNTBLANK(R13:AO13) -> 18 | I13: =COUNTIF(R13:AO13,"FJ") -> 0 | J13: =COUNTIF(R13:AO13,"RJ") -> 0 | K13: =COUNTIF(R13:AO13,"SAFJ") -> 0 | L13: =COUNTIF(R13:AO13,"F") -> 0 | M13: =COUNTIF(R13:AO13,"R") -> 0 | N13: =COUNTIF(R13:AO13,"SAF") -> 0 | O13: =(L13+(M13/2))+(N13/2) -> 0 | P13: =I13+L13 -> 0 | Q13: =SUM(I13:N13) -> 0 | V13: x | W13: x | AC13: x | AD13: x | AJ13: x | AK13: x | AQ13: =H13*B$49 -> 99
A14: 11 | B14: =Listado!B14 -> Gil Fuertes | C14: =Listado!C14 -> Héctor | D14: =Listado!D14 -> Héctor | E14: =Listado!E14 -> hector.gil@tajamar365.com | H14: =COUNTBLANK(R14:AO14) -> 18 | I14: =COUNTIF(R14:AO14,"FJ") -> 0 | J14: =COUNTIF(R14:AO14,"RJ") -> 0 | K14: =COUNTIF(R14:AO14,"SAFJ") -> 0 | L14: =COUNTIF(R14:AO14,"F") -> 0 | M14: =COUNTIF(R14:AO14,"R") -> 0 | N14: =COUNTIF(R14:AO14,"SAF") -> 0 | O14: =(L14+(M14/2))+(N14/2) -> 0 | P14: =I14+L14 -> 0 | Q14: =SUM(I14:N14) -> 0 | V14: x | W14: x | AC14: x | AD14: x | AJ14: x | AK14: x | AQ14: =H14*B$49 -> 99
A15: 12 | B15: =Listado!B15 -> Gonzalo Lucas | C15: =Listado!C15 -> Pablo | D15: =Listado!D15 -> Pablo | E15: =Listado!E15 -> pablo.gonzalo@tajamar365.com | H15: =COUNTBLANK(R15:AO15) -> 18 | I15: =COUNTIF(R15:AO15,"FJ") -> 0 | J15: =COUNTIF(R15:AO15,"RJ") -> 0 | K15: =COUNTIF(R15:AO15,"SAFJ") -> 0 | L15: =COUNTIF(R15:AO15,"F") -> 0 | M15: =COUNTIF(R15:AO15,"R") -> 0 | N15: =COUNTIF(R15:AO15,"SAF") -> 0 | O15: =(L15+(M15/2))+(N15/2) -> 0 | P15: =I15+L15 -> 0 | Q15: =SUM(I15:N15) -> 0 | V15: x | W15: x | AC15: x | AD15: x | AJ15: x | AK15: x | AQ15: =H15*B$49 -> 99
... A29: 26 | B29: =Listado!B29 -> Vázquez Martínez | C29: =Listado!C29 -> Iván | D29: =Listado!D29 -> Iván | E29: =Listado!E29 -> ivan.vazquez@tajamar365.com | H29: =COUNTBLANK(R29:AO29) -> 18 | I29: =COUNTIF(R29:AO29,"FJ") -> 0 | J29: =COUNTIF(R29:AO29,"RJ") -> 0 | K29: =COUNTIF(R29:AO29,"SAFJ") -> 0 | L29: =COUNTIF(R29:AO29,"F") -> 0 | M29: =COUNTIF(R29:AO29,"R") -> 0 | N29: =COUNTIF(R29:AO29,"SAF") -> 0 | O29: =(L29+(M29/2))+(N29/2) -> 0 | P29: =I29+L29 -> 0 | Q29: =SUM(I29:N29) -> 0 | V29: x | W29: x | AC29: x | AD29: x | AJ29: x | AK29: x | AQ29: =H29*B$49 -> 99
H31: CLAVE PROFESOR (PGS):
H32: CLAVE COORDINADOR (JBB):
A33: CLAVES (escribir en mayúsculas)
A34: ASISTENCIA | C34: Dejar en blanco
A35: PRESENTACIÓN PROYECTO EN CASA | B35: PPC
A36: FALTA JUSTIFICADA | B36: FJ | C36: (aporta justificante original válido)
A37: RETRASO JUSTIFICADO | B37: RJ | C37: (aporta justificante original válido) | G37: INSERTAR COMENTARIOS PARA ESPECIFICAR A QUÉ HORA LLEGA TARDE UN ALUMNO O A QUÉ HORA SE MARCHA UN ALUMNO
A38: SALIDA ANTES DE FINALIZAR JUSTIFICADA | B38: SAFJ | C38: (aporta justificante original válido)
A39: FALTA | B39: F | C39: (si falta más del 50% de la jornada, computar como falta)
A40: RETRASO | B40: R | C40: (si no está al comienzo de la clase. Se considera retraso si se incorpora justo después del descanso, a las 12:00
A41: SALIDA ANTES DE FINALIZAR CLASE | B41: SAF | C41: (si no está al finalizar la clase). Si se marcha a partir de la mitad de la jornada
A42: NO SE HA INCORPORADO TODAVÍA | B42: X
A43: CLAVE PROFESOR | B43: Escribir iniciales | C43: Sobre fondo de color verde
A47: NO MODIFICAR
A48: DÍAS LECTIVOS MES: | B48: =COUNTBLANK(R1:AO1) -> 18 | C48: se autocalcula
A49: HORAS DÍA: | B49: 5.5
A50: HORAS LECTIVAS MES: | B50: =B48*B49 -> 99 | C50: OBSERVACIONES (si hay días con menos de X horas lectivas, poner el nº de horas lectivas al mes a mano)
A52: TOTAL HORAS CURSO: | B52: 814

Sheet Febrero
A1: hotm | H1: ZONA DE AUTOCÁLCULO | W1: x | X1: x | AD1: x | AE1: x | AK1: x | AL1: x | AR1: NO MODIFICAR
H2: DÍAS | R2: Lunes | S2: Martes | T2: Miércoles | U2: Jueves | V2: Viernes | W2: Sábado | X2: Domingo | Y2: Lunes | Z2: Martes | AA2: Miércoles | AB2: Jueves | AC2: Viernes | AD2: Sábado | AE2: Domingo | AF2: Lunes | AG2: Martes | AH2: Miércoles | AI2: Jueves | AJ2: Viernes | AK2: Sábado | AL2: Domingo | AM2: Lunes | AN2: Martes | AO2: Miércoles | AP2: Jueves | AR2: HORAS
A3: Nº | B3: APELLIDOS | C3: NOMBRE | D3: Nick name | E3: Email 365 | F3: Email | G3: Teléfono | H3: A | I3: FJ | J3: RJ | K3: SAFJ | L3: F | M3: R | N3: SAF | O3: TOTAL FALTAS MES | P3: Nº de Faltas Total F Mes | Q3: Nº de Faltas Total F y R Mes | R3: 46055 | S3: 46056 | T3: 46057 | U3: 46058 | V3: 46059 | W3: 46060 | X3: 46061 | Y3: 46062 | Z3: 46063 | AA3: 46064 | AB3: 46065 | AC3: 46066 | AD3: 46067 | AE3: 46068 | AF3: 46069 | AG3: 46070 | AH3: 46071 | AI3: 46072 | AJ3: 46073 | AK3: 46074 | AL3: 46075 | AM3: 46076 | AN3: 46077 | AO3: 46078 | AP3: 46079 | AR3: ASISTENCIA
A4: 1 | B4: =Listado!B4 -> Alonso Mansilla | C4: =Listado!C4 -> Javier | D4: =Listado!D4 -> Javi | E4: =Listado!E4 -> javier.alonsomansilla@tajamar365.com | H4: =COUNTBLANK(R4:AP4) -> 19 | I4: =COUNTIF(R4:AP4,"FJ") -> 0 | J4: =COUNTIF(R4:AP4,"RJ") -> 0 | K4: =COUNTIF(R4:AP4,"SAFJ") -> 0 | L4: =COUNTIF(R4:AP4,"F") -> 0 | M4: =COUNTIF(R4:AP4,"R") -> 0 | N4: =COUNTIF(R4:AP4,"SAF") -> 0 | O4: =(L4+(M4/2))+(N4/2) -> 0 | P4: =I4+L4 -> 0 | Q4: =SUM(I4:N4) -> 0 | W4: x | X4: x | AD4: x | AE4: x | AK4: x | AL4: x | AR4: =H4*B$49 -> 104.5
A5: 2 | B5: =Listado!B5 -> Barbacid Fernández | C5: =Listado!C5 -> Alberto | D5: =Listado!D5 -> Alberto | E5: =Listado!E5 -> alberto.barbacid@tajamar365.com | H5: =COUNTBLANK(R5:AP5) -> 19 | I5: =COUNTIF(R5:AP5,"FJ") -> 0 | J5: =COUNTIF(R5:AP5,"RJ") -> 0 | K5: =COUNTIF(R5:AP5,"SAFJ") -> 0 | L5: =COUNTIF(R5:AP5,"F") -> 0 | M5: =COUNTIF(R5:AP5,"R") -> 0 | N5: =COUNTIF(R5:AP5,"SAF") -> 0 | O5: =(L5+(M5/2))+(N5/2) -> 0 | P5: =I5+L5 -> 0 | Q5: =SUM(I5:N5) -> 0 | W5: x | X5: x | AD5: x | AE5: x | AK5: x | AL5: x | AR5: =H5*B$49 -> 104.5
A6: 3 | B6: =Listado!B6 -> Bayas Sarzosa | C6: =Listado!C6 -> Kevin | D6: =Listado!D6 -> Kevin | E6: =Listado!E6 -> kevin.bayas@tajamar365.com | H6: =COUNTBLANK(R6:AP6) -> 19 | I6: =COUNTIF(R6:AP6,"FJ") -> 0 | J6: =COUNTIF(R6:AP6,"RJ") -> 0 | K6: =COUNTIF(R6:AP6,"SAFJ") -> 0 | L6: =COUNTIF(R6:AP6,"F") -> 0 | M6: =COUNTIF(R6:AP6,"R") -> 0 | N6: =COUNTIF(R6:AP6,"SAF") -> 0 | O6: =(L6+(M6/2))+(N6/2) -> 0 | P6: =I6+L6 -> 0 | Q6: =SUM(I6:N6) -> 0 | W6: x | X6: x | AD6: x | AE6: x | AK6: x | AL6: x | AR6: =H6*B$49 -> 104.5
A7: 4 | B7: =Listado!B7 -> Cánovas López | C7: =Listado!C7 -> Alejandro | D7: =Listado!D7 -> Alex | E7: =Listado!E7 -> alejandro.canovas@tajamar365.com | H7: =COUNTBLANK(R7:AP7) -> 19 | I7: =COUNTIF(R7:AP7,"FJ") -> 0 | J7: =COUNTIF(R7:AP7,"RJ") -> 0 | K7: =COUNTIF(R7:AP7,"SAFJ") -> 0 | L7: =COUNTIF(R7:AP7,"F") -> 0 | M7: =COUNTIF(R7:AP7,"R") -> 0 | N7: =COUNTIF(R7:AP7,"SAF") -> 0 | O7: =(L7+(M7/2))+(N7/2) -> 0 | P7: =I7+L7 -> 0 | Q7: =SUM(I7:N7) -> 0 | W7: x | X7: x | AD7: x | AE7: x | AK7: x | AL7: x | AR7: =H7*B$49 -> 104.5
A8: 5 | B8: =Listado!B8 -> Cardona Hernández | C8: =Listado!C8 -> Diego | D8: =Listado!D8 -> Diego | E8: =Listado!E8 -> diego.cardona@tajamar365.com | H8: =COUNTBLANK(R8:AP8) -> 19 | I8: =COUNTIF(R8:AP8,"FJ") -> 0 | J8: =COUNTIF(R8:AP8,"RJ") -> 0 | K8: =COUNTIF(R8:AP8,"SAFJ") -> 0 | L8: =COUNTIF(R8:AP8,"F") -> 0 | M8: =COUNTIF(R8:AP8,"R") -> 0 | N8: =COUNTIF(R8:AP8,"SAF") -> 0 | O8: =(L8+(M8/2))+(N8/2) -> 0 | P8: =I8+L8 -> 0 | Q8: =SUM(I8:N8) -> 0 | W8: x | X8: x | AD8: x | AE8: x | AK8: x | AL8: x | AR8: =H8*B$49 -> 104.5
A9: 6 | B9: =Listado!B9 -> Casco Valero | C9: =Listado!C9 -> Álvaro | D9: =Listado!D9 -> Álvaro | E9: =Listado!E9 -> alvaro.casco@tajamar365.com | H9: =COUNTBLANK(R9:AP9) -> 19 | I9: =COUNTIF(R9:AP9,"FJ") -> 0 | J9: =COUNTIF(R9:AP9,"RJ") -> 0 | K9: =COUNTIF(R9:AP9,"SAFJ") -> 0 | L9: =COUNTIF(R9:AP9,"F") -> 0 | M9: =COUNTIF(R9:AP9,"R") -> 0 | N9: =COUNTIF(R9:AP9,"SAF") -> 0 | O9: =(L9+(M9/2))+(N9/2) -> 0 | P9: =I9+L9 -> 0 | Q9: =SUM(I9:N9) -> 0 | W9: x | X9: x | AD9: x | AE9: x | AK9: x | AL9: x | AR9: =H9*B$49 -> 104.5
A10: 7 | B10: =Listado!B10 -> Cobo Marcos | C10: =Listado!C10 -> Alejandro | D10: =Listado!D10 -> Alex | E10: =Listado!E10 -> alejandro.cobo@tajamar365.com | H10: =COUNTBLANK(R10:AP10) -> 19 | I10: =COUNTIF(R10:AP10,"FJ") -> 0 | J10: =COUNTIF(R10:AP10,"RJ") -> 0 | K10: =COUNTIF(R10:AP10,"SAFJ") -> 0 | L10: =COUNTIF(R10:AP10,"F") -> 0 | M10: =COUNTIF(R10:AP10,"R") -> 0 | N10: =COUNTIF(R10:AP10,"SAF") -> 0 | O10: =(L10+(M10/2))+(N10/2) -> 0 | P10: =I10+L10 -> 0 | Q10: =SUM(I10:N10) -> 0 | W10: x | X10: x | AD10: x | AE10: x | AK10: x | AL10: x | AR10: =H10*B$49 -> 104.5
A11: 8 | B11: =Listado!B11 -> Galán Castro | C11: =Listado!C11 -> Asil | D11: =Listado!D11 -> Asil | E11: =Listado!E11 -> asil.galan@tajamar365.com | H11: =COUNTBLANK(R11:AP11) -> 19 | I11: =COUNTIF(R11:AP11,"FJ") -> 0 | J11: =COUNTIF(R11:AP11,"RJ") -> 0 | K11: =COUNTIF(R11:AP11,"SAFJ") -> 0 | L11: =COUNTIF(R11:AP11,"F") -> 0 | M11: =COUNTIF(R11:AP11,"R") -> 0 | N11: =COUNTIF(R11:AP11,"SAF") -> 0 | O11: =(L11+(M11/2))+(N11/2) -> 0 | P11: =I11+L11 -> 0 | Q11: =SUM(I11:N11) -> 0 | W11: x | X11: x | AD11: x | AE11: x | AK11: x | AL11: x | AR11: =H11*B$49 -> 104.5
A12: 9 | B12: =Listado!B12 -> García Martín | C12: =Listado!C12 -> Alonso | D12: =Listado!D12 -> Alonso | E12: =Listado!E12 -> alonso.garcia@tajamar365.com | H12: =COUNTBLANK(R12:AP12) -> 19 | I12: =COUNTIF(R12:AP12,"FJ") -> 0 | J12: =COUNTIF(R12:AP12,"RJ") -> 0 | K12: =COUNTIF(R12:AP12,"SAFJ") -> 0 | L12: =COUNTIF(R12:AP12,"F") -> 0 | M12: =COUNTIF(R12:AP12,"R") -> 0 | N12: =COUNTIF(R12:AP12,"SAF") -> 0 | O12: =(L12+(M12/2))+(N12/2) -> 0 | P12: =I12+L12 -> 0 | Q12: =SUM(I12:N12) -> 0 | W12: x | X12: x | AD12: x | AE12: x | AK12: x | AL12: x | AR12: =H12*B$49 -> 104.5
A13: 10 | B13: =Listado!B13 -> García Muñoz | C13: =Listado!C13 -> Raúl | D13: =Listado!D13 -> Raúl | E13: =Listado!E13 -> raul.garciamunoz@tajamar365.com | H13: =COUNTBLANK(R13:AP13) -> 19 | I13: =COUNTIF(R13:AP13,"FJ") -> 0 | J13: =COUNTIF(R13:AP13,"RJ") -> 0 | K13: =COUNTIF(R13:AP13,"SAFJ") -> 0 | L13: =COUNTIF(R13:AP13,"F") -> 0 | M13: =COUNTIF(R13:AP13,"R") -> 0 | N13: =COUNTIF(R13:AP13,"SAF") -> 0 | O13: =(L13+(M13/2))+(N13/2) -> 0 | P13: =I13+L13 -> 0 | Q13: =SUM(I13:N13) -> 0 | W13: x | X13: x | AD13: x | AE13: x | AK13: x | AL13: x | AR13: =H13*B$49 -> 104.5
